Workbook

Sheet 30 mA
A1: Tempo (s) | B1: Trecho 1 | C1: Trecho 2 | D1: Trecho 3 | E1: Trecho 4 | F1: Trecho 5 | G1: Trecho 6 | H1: Trecho 7 | I1: Trecho 8 | J1: Trecho 9 | K1: Trecho 10 | L1: MÉDIA | M1: Min. (A) | N1: Max. (A) | O1: Intervalo de confiança (t-Student, 95 %) | P1: Iq (ruído de quant., em A) --> | Q1: =0.00000001*12^(-0.5) -> 2.8867513e-09 | R1: Resol. (em A) --> | S1: 1e-08
A2: 1 | B2: =Plan11!$G11 -> 5.9154e-07 | C2: =Plan12!$G11 -> 5.396e-07 | D2: =Plan13!$G11 -> 5.7637e-07 | E2: =Plan14!$G11 -> 5.6141e-07 | F2: =Plan15!$G11 -> 5.7503e-07 | G2: =Plan16!$G11 -> 5.9695e-07 | H2: =Plan17!$G11 -> 5.9699e-07 | I2: =Plan18!$G11 -> 6.183e-07 | J2: =Plan19!$G11 -> 6.0384e-07 | K2: =Plan20!$G11 -> 5.8292e-07 | L2: =AVERAGE(B2:K2) -> 5.84295e-07 | M2: =L2-O2 -> 5.6815044e-07 | N2: =L2+O2 -> 6.0043956e-07 | O2: =_xlfn.CONFIDENCE.T(0.05,_xlfn.STDEV.S(B2:K2),COUNTA(B2:K2)) -> 1.6144562e-08
A3: 2 | B3: =Plan11!$G12 -> 3.4556e-07 | C3: =Plan12!$G12 -> 3.2512e-07 | D3: =Plan13!$G12 -> 3.2921e-07 | E3: =Plan14!$G12 -> 3.2249e-07 | F3: =Plan15!$G12 -> 3.2361e-07 | G3: =Plan16!$G12 -> 3.3995e-07 | H3: =Plan17!$G12 -> 3.5488e-07 | I3: =Plan18!$G12 -> 3.5185e-07 | J3: =Plan19!$G12 -> 3.5096e-07 | K3: =Plan20!$G12 -> 3.3902e-07 | L3: =AVERAGE(B3:K3) -> 3.38265e-07 | M3: =L3-O3 -> 3.2935312e-07 | N3: =L3+O3 -> 3.4717688e-07 | O3: =_xlfn.CONFIDENCE.T(0.05,_xlfn.STDEV.S(B3:K3),COUNTA(B3:K3)) -> 8.9118767e-09
A4: 3 | B4: =Plan11!$G13 -> 1.782e-07 | C4: =Plan12!$G13 -> 1.727e-07 | D4: =Plan13!$G13 -> 1.6361e-07 | E4: =Plan14!$G13 -> 1.5768e-07 | F4: =Plan15!$G13 -> 1.6153e-07 | G4: =Plan16!$G13 -> 1.6609e-07 | H4: =Plan17!$G13 -> 1.8766e-07 | I4: =Plan18!$G13 -> 1.7436e-07 | J4: =Plan19!$G13 -> 1.7182e-07 | K4: =Plan20!$G13 -> 1.6717e-07 | L4: =AVERAGE(B4:K4) -> 1.70082e-07 | M4: =L4-O4 -> 1.6378978e-07 | N4: =L4+O4 -> 1.7637422e-07 | O4: =_xlfn.CONFIDENCE.T(0.05,_xlfn.STDEV.S(B4:K4),COUNTA(B4:K4)) -> 6.2922171e-09
A5: 4 | B5: =Plan11!$G14 -> 1.7864e-07 | C5: =Plan12!$G14 -> 1.7407e-07 | D5: =Plan13!$G14 -> 1.7528e-07 | E5: =Plan14!$G14 -> 1.6554e-07 | F5: =Plan15!$G14 -> 1.7611e-07 | G5: =Plan16!$G14 -> 1.8044e-07 | H5: =Plan17!$G14 -> 1.809e-07 | I5: =Plan18!$G14 -> 1.8896e-07 | J5: =Plan19!$G14 -> 1.8177e-07 | K5: =Plan20!$G14 -> 1.7744e-07 | L5: =AVERAGE(B5:K5) -> 1.77915e-07 | M5: =L5-O5 -> 1.7357664e-07 | N5: =L5+O5 -> 1.8225336e-07 | O5: =_xlfn.CONFIDENCE.T(0.05,_xlfn.STDEV.S(B5:K5),COUNTA(B5:K5)) -> 4.3383646e-09
A6: 5 | B6: =Plan11!$G15 -> 1.6847e-07 | C6: =Plan12!$G15 -> 1.7347e-07 | D6: =Plan13!$G15 -> 1.713e-07 | E6: =Plan14!$G15 -> 1.6223e-07 | F6: =Plan15!$G15 -> 1.7092e-07 | G6: =Plan16!$G15 -> 1.7636e-07 | H6: =Plan17!$G15 -> 1.7523e-07 | I6: =Plan18!$G15 -> 1.8085e-07 | J6: =Plan19!$G15 -> 1.7382e-07 | K6: =Plan20!$G15 -> 1.7579e-07 | L6: =AVERAGE(B6:K6) -> 1.72844e-07 | M6: =L6-O6 -> 1.692273e-07 | N6: =L6+O6 -> 1.764607e-07 | O6: =_xlfn.CONFIDENCE.T(0.05,_xlfn.STDEV.S(B6:K6),COUNTA(B6:K6)) -> 3.6166953e-09
A7: 6 | B7: =Plan11!$G16 -> 1.2172e-07 | C7: =Plan12!$G16 -> 1.2827e-07 | D7: =Plan13!$G16 -> 1.235e-07 | E7: =Plan14!$G16 -> 1.2031e-07 | F7: =Plan15!$G16 -> 1.2921e-07 | G7: =Plan16!$G16 -> 1.2972e-07 | H7: =Plan17!$G16 -> 1.2465e-07 | I7: =Plan18!$G16 -> 1.362e-07 | J7: =Plan19!$G16 -> 1.3347e-07 | K7: =Plan20!$G16 -> 1.3364e-07 | L7: =AVERAGE(B7:K7) -> 1.28069e-07 | M7: =L7-O7 -> 1.2419853e-07 | N7: =L7+O7 -> 1.3193947e-07 | O7: =_xlfn.CONFIDENCE.T(0.05,_xlfn.STDEV.S(B7:K7),COUNTA(B7:K7)) -> 3.8704657e-09
A8: 7 | B8: =Plan11!$G17 -> 9.6563e-08 | C8: =Plan12!$G17 -> 9.5923e-08 | D8: =Plan13!$G17 -> 9.2414e-08 | E8: =Plan14!$G17 -> 9.94e-08 | F8: =Plan15!$G17 -> 1.0344e-07 | G8: =Plan16!$G17 -> 1.0647e-07 | H8: =Plan17!$G17 -> 8.8365e-08 | I8: =Plan18!$G17 -> 1.1049e-07 | J8: =Plan19!$G17 -> 1.1828e-07 | K8: =Plan20!$G17 -> 1.1329e-07 | L8: =AVERAGE(B8:K8) -> 1.024635e-07 | M8: =L8-O8 -> 9.5570849e-08 | N8: =L8+O8 -> 1.0935615e-07 | O8: =_xlfn.CONFIDENCE.T(0.05,_xlfn.STDEV.S(B8:K8),COUNTA(B8:K8)) -> 6.8926505e-09
A9: 8 | B9: =Plan11!$G18 -> 1.0913e-07 | C9: =Plan12!$G18 -> 1.0356e-07 | D9: =Plan13!$G18 -> 1.0613e-07 | E9: =Plan14!$G18 -> 1.1054e-07 | F9: =Plan15!$G18 -> 1.0771e-07 | G9: =Plan16!$G18 -> 1.1263e-07 | H9: =Plan17!$G18 -> 1.0126e-07 | I9: =Plan18!$G18 -> 1.1984e-07 | J9: =Plan19!$G18 -> 1.1668e-07 | K9: =Plan20!$G18 -> 1.2133e-07 | L9: =AVERAGE(B9:K9) -> 1.10881e-07 | M9: =L9-O9 -> 1.0606389e-07 | N9: =L9+O9 -> 1.1569811e-07 | O9: =_xlfn.CONFIDENCE.T(0.05,_xlfn.STDEV.S(B9:K9),COUNTA(B9:K9)) -> 4.8171077e-09
A10: 9 | B10: =Plan11!$G19 -> 1.0035e-07 | C10: =Plan12!$G19 -> 9.1438e-08 | D10: =Plan13!$G19 -> 9.279e-08 | E10: =Plan14!$G19 -> 1.016e-07 | F10: =Plan15!$G19 -> 9.1865e-08 | G10: =Plan16!$G19 -> 9.7977e-08 | H10: =Plan17!$G19 -> 8.8418e-08 | I10: =Plan18!$G19 -> 1.0714e-07 | J10: =Plan19!$G19 -> 1.0461e-07 | K10: =Plan20!$G19 -> 1.071e-07 | L10: =AVERAGE(B10:K10) -> 9.83288e-08 | M10: =L10-O10 -> 9.3400847e-08 | N10: =L10+O10 -> 1.0325675e-07 | O10: =_xlfn.CONFIDENCE.T(0.05,_xlfn.STDEV.S(B10:K10),COUNTA(B10:K10)) -> 4.9279532e-09
A11: 10 | B11: =Plan11!$G20 -> 8.1869e-08 | C11: =Plan12!$G20 -> 7.1033e-08 | D11: =Plan13!$G20 -> 7.226e-08 | E11: =Plan14!$G20 -> 8.5833e-08 | F11: =Plan15!$G20 -> 7.0396e-08 | G11: =Plan16!$G20 -> 7.7421e-08 | H11: =Plan17!$G20 -> 6.555e-08 | I11: =Plan18!$G20 -> 8.701e-08 | J11: =Plan19!$G20 -> 9.2485e-08 | K11: =Plan20!$G20 -> 8.9442e-08 | L11: =AVERAGE(B11:K11) -> 7.93299e-08 | M11: =L11-O11 -> 7.2690818e-08 | N11: =L11+O11 -> 8.5968982e-08 | O11: =_xlfn.CONFIDENCE.T(0.05,_xlfn.STDEV.S(B11:K11),COUNTA(B11:K11)) -> 6.6390818e-09
A12: 11 | B12: =Plan11!$G21 -> 8.7599e-08 | C12: =Plan12!$G21 -> 7.5056e-08 | D12: =Plan13!$G21 -> 8.2051e-08 | E12: =Plan14!$G21 -> 8.9861e-08 | F12: =Plan15!$G21 -> 7.3767e-08 | G12: =Plan16!$G21 -> 8.3232e-08 | H12: =Plan17!$G21 -> 7.6307e-08 | I12: =Plan18!$G21 -> 9.4083e-08 | J12: =Plan19!$G21 -> 9.0565e-08 | K12: =Plan20!$G21 -> 9.164e-08 | L12: =AVERAGE(B12:K12) -> 8.44161e-08 | M12: =L12-O12 -> 7.9100226e-08 | N12: =L12+O12 -> 8.9731974e-08 | O12: =_xlfn.CONFIDENCE.T(0.05,_xlfn.STDEV.S(B12:K12),COUNTA(B12:K12)) -> 5.3158744e-09
A13: 12 | B13: =Plan11!$G22 -> 8.5464e-08 | C13: =Plan12!$G22 -> 7.5651e-08 | D13: =Plan13!$G22 -> 8.1118e-08 | E13: =Plan14!$G22 -> 8.7677e-08 | F13: =Plan15!$G22 -> 7.0502e-08 | G13: =Plan16!$G22 -> 8.2073e-08 | H13: =Plan17!$G22 -> 7.4947e-08 | I13: =Plan18!$G22 -> 9.3215e-08 | J13: =Plan19!$G22 -> 8.6169e-08 | K13: =Plan20!$G22 -> 8.5001e-08 | L13: =AVERAGE(B13:K13) -> 8.21817e-08 | M13: =L13-O13 -> 7.7300108e-08 | N13: =L13+O13 -> 8.7063292e-08 | O13: =_xlfn.CONFIDENCE.T(0.05,_xlfn.STDEV.S(B13:K13),COUNTA(B13:K13)) -> 4.8815917e-09
... A88: 103 | B88: =Plan11!$G97 -> 4.1109e-08 | C88: =Plan12!$G97 -> 4.5803e-08 | D88: =Plan13!$G97 -> 3.1737e-08 | E88: =Plan14!$G97 -> 3.2713e-08 | F88: =Plan15!$G97 -> 2.9351e-08 | G88: =Plan16!$G97 -> 2.4319e-08 | H88: =Plan17!$G97 -> 4.3615e-08 | I88: =Plan18!$G97 -> 3.0335e-08 | J88: =Plan19!$G97 -> 4.3009e-08 | K88: =Plan20!$G97 -> 3.3646e-08 | L88: =AVERAGE(B88:K88) -> 3.55637e-08 | M88: =L88-O88 -> 3.0368517e-08 | N88: =L88+O88 -> 4.0758883e-08 | O88: =_xlfn.CONFIDENCE.T(0.05,_xlfn.STDEV.S(B88:K88),COUNTA(B88:K88)) -> 5.1951827e-09

Sheet Plan11
B1: STATISTICS | C1: FOR | D1: FILE: | E1: 30 | F1: mA | G1: NPLC | H1: 20 | I1: ini | J1: 2023 | K1: trecho | L1: 01.txt
B2: Frequency | C2: Data | D2: Points | E2: 1 | F2: thru | G2: 419 | H2: of | I2: 419
B3: Maximum | C3: = | D3: 0.03001419
B4: Minimum | C4: = | D4: 0.03001177
B5: Average | C5: = | D5: 0.03001331
B6: Sigma | C6: Type: | D6: Overlapping | E6: Allan
B7: Confidence | C7: Factor | D7: = | E7: 0.683
B8: Deadtime | C8: T/Tau | D8: = | E8: 1
B10: AF | C10: Tau | D10: # | E10: Alpha | F10: Min | G10: Sigma | H10: Sigma | I10: Max | J10: Sigma
B11: 1 | C11: 1 | D11: 418 | E11: 1 | F11: 0 | G11: 5.9154e-07 | H11: 0
B12: 2 | C12: 2 | D12: 416 | E12: 1 | F12: 0 | G12: 3.4556e-07 | H12: 0
B13: 3 | C13: 3 | D13: 414 | E13: 0 | F13: 0 | G13: 1.782e-07 | H13: 0
B14: 4 | C14: 4 | D14: 412 | E14: 0 | F14: 0 | G14: 1.7864e-07 | H14: 0
B15: 5 | C15: 5 | D15: 410 | E15: 1 | F15: 0 | G15: 1.6847e-07 | H15: 0
B16: 6 | C16: 6 | D16: 408 | E16: 0 | F16: 0 | G16: 1.2172e-07 | H16: 0
B17: 7 | C17: 7 | D17: 406 | E17: 0 | F17: 0 | G17: 9.6563e-08 | H17: 0
B18: 8 | C18: 8 | D18: 404 | E18: 0 | F18: 0 | G18: 1.0913e-07 | H18: 0
B19: 9 | C19: 9 | D19: 402 | E19: 0 | F19: 0 | G19: 1.0035e-07 | H19: 0
B20: 10 | C20: 10 | D20: 400 | E20: 0 | F20: 0 | G20: 8.1869e-08 | H20: 0
B21: 11 | C21: 11 | D21: 398 | E21: 0 | F21: 0 | G21: 8.7599e-08 | H21: 0
B22: 12 | C22: 12 | D22: 396 | E22: 0 | F22: 0 | G22: 8.5464e-08 | H22: 0
... B97: 103 | C97: 103 | D97: 214 | E97: 0 | F97: 0 | G97: 4.1109e-08 | H97: 0

Sheet Plan12
B1: STATISTICS | C1: FOR | D1: FILE: | E1: 30 | F1: mA | G1: NPLC | H1: 20 | I1: ini | J1: 2023 | K1: trecho | L1: 02.txt
B2: Frequency | C2: Data | D2: Points | E2: 1 | F2: thru | G2: 420 | H2: of | I2: 420
B3: Maximum | C3: = | D3: 0.03001414
B4: Minimum | C4: = | D4: 0.03001177
B5: Average | C5: = | D5: 0.03001321
B6: Sigma | C6: Type: | D6: Overlapping | E6: Allan
B7: Confidence | C7: Factor | D7: = | E7: 0.683
B8: Deadtime | C8: T/Tau | D8: = | E8: 1
B10: AF | C10: Tau | D10: # | E10: Alpha | F10: Min | G10: Sigma | H10: Sigma | I10: Max | J10: Sigma
B11: 1 | C11: 1 | D11: 419 | E11: 1 | F11: 0 | G11: 5.396e-07 | H11: 0
B12: 2 | C12: 2 | D12: 417 | E12: 1 | F12: 0 | G12: 3.2512e-07 | H12: 0
B13: 3 | C13: 3 | D13: 415 | E13: 0 | F13: 0 | G13: 1.727e-07 | H13: 0
B14: 4 | C14: 4 | D14: 413 | E14: 0 | F14: 0 | G14: 1.7407e-07 | H14: 0
B15: 5 | C15: 5 | D15: 411 | E15: 1 | F15: 0 | G15: 1.7347e-07 | H15: 0
B16: 6 | C16: 6 | D16: 409 | E16: 0 | F16: 0 | G16: 1.2827e-07 | H16: 0
B17: 7 | C17: 7 | D17: 407 | E17: 0 | F17: 0 | G17: 9.5923e-08 | H17: 0
B18: 8 | C18: 8 | D18: 405 | E18: 0 | F18: 0 | G18: 1.0356e-07 | H18: 0
B19: 9 | C19: 9 | D19: 403 | E19: 0 | F19: 0 | G19: 9.1438e-08 | H19: 0
B20: 10 | C20: 10 | D20: 401 | E20: 0 | F20: 0 | G20: 7.1033e-08 | H20: 0
B21: 11 | C21: 11 | D21: 399 | E21: 0 | F21: 0 | G21: 7.5056e-08 | H21: 0
B22: 12 | C22: 12 | D22: 397 | E22: 0 | F22: 0 | G22: 7.5651e-08 | H22: 0
... B97: 103 | C97: 103 | D97: 215 | E97: -1 | F97: 0 | G97: 4.5803e-08 | H97: 0

Sheet Plan13
B1: STATISTICS | C1: FOR | D1: FILE: | E1: 30 | F1: mA | G1: NPLC | H1: 20 | I1: ini | J1: 2023 | K1: trecho | L1: 03.txt
B2: Frequency | C2: Data | D2: Points | E2: 1 | F2: thru | G2: 419 | H2: of | I2: 419
B3: Maximum | C3: = | D3: 0.03001401
B4: Minimum | C4: = | D4: 0.03001163
B5: Average | C5: = | D5: 0.03001317
B6: Sigma | C6: Type: | D6: Overlapping | E6: Allan
B7: Confidence | C7: Factor | D7: = | E7: 0.683
B8: Deadtime | C8: T/Tau | D8: = | E8: 1
B10: AF | C10: Tau | D10: # | E10: Alpha | F10: Min | G10: Sigma | H10: Sigma | I10: Max | J10: Sigma
B11: 1 | C11: 1 | D11: 418 | E11: 1 | F11: 0 | G11: 5.7637e-07 | H11: 0
B12: 2 | C12: 2 | D12: 416 | E12: 1 | F12: 0 | G12: 3.2921e-07 | H12: 0
B13: 3 | C13: 3 | D13: 414 | E13: 0 | F13: 0 | G13: 1.6361e-07 | H13: 0
B14: 4 | C14: 4 | D14: 412 | E14: 0 | F14: 0 | G14: 1.7528e-07 | H14: 0
B15: 5 | C15: 5 | D15: 410 | E15: 2 | F15: 0 | G15: 1.713e-07 | H15: 0
B16: 6 | C16: 6 | D16: 408 | E16: 0 | F16: 0 | G16: 1.235e-07 | H16: 0
B17: 7 | C17: 7 | D17: 406 | E17: 0 | F17: 0 | G17: 9.2414e-08 | H17: 0
B18: 8 | C18: 8 | D18: 404 | E18: 0 | F18: 0 | G18: 1.0613e-07 | H18: 0
B19: 9 | C19: 9 | D19: 402 | E19: 0 | F19: 0 | G19: 9.279e-08 | H19: 0
B20: 10 | C20: 10 | D20: 400 | E20: 0 | F20: 0 | G20: 7.226e-08 | H20: 0
B21: 11 | C21: 11 | D21: 398 | E21: 0 | F21: 0 | G21: 8.2051e-08 | H21: 0
B22: 12 | C22: 12 | D22: 396 | E22: 0 | F22: 0 | G22: 8.1118e-08 | H22: 0
... B97: 103 | C97: 103 | D97: 214 | E97: -1 | F97: 0 | G97: 3.1737e-08 | H97: 0

Sheet Plan14
B1: STATISTICS | C1: FOR | D1: FILE: | E1: 30 | F1: mA | G1: NPLC | H1: 20 | I1: ini | J1: 2023 | K1: trecho | L1: 04.txt
B2: Frequency | C2: Data | D2: Points | E2: 1 | F2: thru | G2: 419 | H2: of | I2: 419
B3: Maximum | C3: = | D3: 0.03001413
B4: Minimum | C4: = | D4: 0.0300117
B5: Average | C5: = | D5: 0.03001312
B6: Sigma | C6: Type: | D6: Overlapping | E6: Allan
B7: Confidence | C7: Factor | D7: = | E7: 0.683
B8: Deadtime | C8: T/Tau | D8: = | E8: 1
B10: AF | C10: Tau | D10: # | E10: Alpha | F10: Min | G10: Sigma | H10: Sigma | I10: Max | J10: Sigma
B11: 1 | C11: 1 | D11: 418 | E11: 1 | F11: 0 | G11: 5.6141e-07 | H11: 0
B12: 2 | C12: 2 | D12: 416 | E12: 1 | F12: 0 | G12: 3.2249e-07 | H12: 0
B13: 3 | C13: 3 | D13: 414 | E13: 0 | F13: 0 | G13: 1.5768e-07 | H13: 0
B14: 4 | C14: 4 | D14: 412 | E14: 0 | F14: 0 | G14: 1.6554e-07 | H14: 0
B15: 5 | C15: 5 | D15: 410 | E15: 1 | F15: 0 | G15: 1.6223e-07 | H15: 0
B16: 6 | C16: 6 | D16: 408 | E16: 0 | F16: 0 | G16: 1.2031e-07 | H16: 0
B17: 7 | C17: 7 | D17: 406 | E17: 0 | F17: 0 | G17: 9.94e-08 | H17: 0
B18: 8 | C18: 8 | D18: 404 | E18: 0 | F18: 0 | G18: 1.1054e-07 | H18: 0
B19: 9 | C19: 9 | D19: 402 | E19: 0 | F19: 0 | G19: 1.016e-07 | H19: 0
B20: 10 | C20: 10 | D20: 400 | E20: 0 | F20: 0 | G20: 8.5833e-08 | H20: 0
B21: 11 | C21: 11 | D21: 398 | E21: 0 | F21: 0 | G21: 8.9861e-08 | H21: 0
B22: 12 | C22: 12 | D22: 396 | E22: 0 | F22: 0 | G22: 8.7677e-08 | H22: 0
... B97: 103 | C97: 103 | D97: 214 | E97: 0 | F97: 0 | G97: 3.2713e-08 | H97: 0

Sheet Plan15
B1: STATISTICS | C1: FOR | D1: FILE: | E1: 30 | F1: mA | G1: NPLC | H1: 20 | I1: ini | J1: 2023 | K1: trecho | L1: 05.txt
B2: Frequency | C2: Data | D2: Points | E2: 1 | F2: thru | G2: 418 | H2: of | I2: 418
B3: Maximum | C3: = | D3: 0.03001405
B4: Minimum | C4: = | D4: 0.03001163
B5: Average | C5: = | D5: 0.0300131
B6: Sigma | C6: Type: | D6: Overlapping | E6: Allan
B7: Confidence | C7: Factor | D7: = | E7: 0.683
B8: Deadtime | C8: T/Tau | D8: = | E8: 1
B10: AF | C10: Tau | D10: # | E10: Alpha | F10: Min | G10: Sigma | H10: Sigma | I10: Max | J10: Sigma
B11: 1 | C11: 1 | D11: 417 | E11: 1 | F11: 0 | G11: 5.7503e-07 | H11: 0
B12: 2 | C12: 2 | D12: 415 | E12: 1 | F12: 0 | G12: 3.2361e-07 | H12: 0
B13: 3 | C13: 3 | D13: 413 | E13: 0 | F13: 0 | G13: 1.6153e-07 | H13: 0
B14: 4 | C14: 4 | D14: 411 | E14: 1 | F14: 0 | G14: 1.7611e-07 | H14: 0
B15: 5 | C15: 5 | D15: 409 | E15: 1 | F15: 0 | G15: 1.7092e-07 | H15: 0
B16: 6 | C16: 6 | D16: 407 | E16: 0 | F16: 0 | G16: 1.2921e-07 | H16: 0
B17: 7 | C17: 7 | D17: 405 | E17: 0 | F17: 0 | G17: 1.0344e-07 | H17: 0
B18: 8 | C18: 8 | D18: 403 | E18: 0 | F18: 0 | G18: 1.0771e-07 | H18: 0
B19: 9 | C19: 9 | D19: 401 | E19: 0 | F19: 0 | G19: 9.1865e-08 | H19: 0
B20: 10 | C20: 10 | D20: 399 | E20: 0 | F20: 0 | G20: 7.0396e-08 | H20: 0
B21: 11 | C21: 11 | D21: 397 | E21: 0 | F21: 0 | G21: 7.3767e-08 | H21: 0
B22: 12 | C22: 12 | D22: 395 | E22: 2 | F22: 0 | G22: 7.0502e-08 | H22: 0
... B97: 103 | C97: 103 | D97: 213 | E97: -1 | F97: 0 | G97: 2.9351e-08 | H97: 0

Sheet Plan16
B1: STATISTICS | C1: FOR | D1: FILE: | E1: -30 | F1: mA | G1: NPLC | H1: 20 | I1: ini | J1: 2023 | K1: trecho | L1: 01.txt
B2: Frequency | C2: Data | D2: Points | E2: 1 | F2: thru | G2: 420 | H2: of | I2: 420
B3: Maximum | C3: = | D3: -0.02998567
B4: Minimum | C4: = | D4: -0.02998833
B5: Average | C5: = | D5: -0.02998665
B6: Sigma | C6: Type: | D6: Overlapping | E6: Allan
B7: Confidence | C7: Factor | D7: = | E7: 0.683
B8: Deadtime | C8: T/Tau | D8: = | E8: 1
B10: AF | C10: Tau | D10: # | E10: Alpha | F10: Min | G10: Sigma | H10: Sigma | I10: Max | J10: Sigma
B11: 1 | C11: 1 | D11: 419 | E11: 1 | F11: 0 | G11: 5.9695e-07 | H11: 0
B12: 2 | C12: 2 | D12: 417 | E12: 1 | F12: 0 | G12: 3.3995e-07 | H12: 0
B13: 3 | C13: 3 | D13: 415 | E13: 0 | F13: 0 | G13: 1.6609e-07 | H13: 0
B14: 4 | C14: 4 | D14: 413 | E14: 0 | F14: 0 | G14: 1.8044e-07 | H14: 0
B15: 5 | C15: 5 | D15: 411 | E15: 2 | F15: 0 | G15: 1.7636e-07 | H15: 0
B16: 6 | C16: 6 | D16: 409 | E16: 0 | F16: 0 | G16: 1.2972e-07 | H16: 0
B17: 7 | C17: 7 | D17: 407 | E17: 0 | F17: 0 | G17: 1.0647e-07 | H17: 0
B18: 8 | C18: 8 | D18: 405 | E18: 1 | F18: 0 | G18: 1.1263e-07 | H18: 0
B19: 9 | C19: 9 | D19: 403 | E19: 0 | F19: 0 | G19: 9.7977e-08 | H19: 0
B20: 10 | C20: 10 | D20: 401 | E20: 0 | F20: 0 | G20: 7.7421e-08 | H20: 0
B21: 11 | C21: 11 | D21: 399 | E21: 0 | F21: 0 | G21: 8.3232e-08 | H21: 0
B22: 12 | C22: 12 | D22: 397 | E22: 0 | F22: 0 | G22: 8.2073e-08 | H22: 0
... B97: 103 | C97: 103 | D97: 215 | E97: 0 | F97: 0 | G97: 2.4319e-08 | H97: 0

Sheet Plan17
B1: STATISTICS | C1: FOR | D1: FILE: | E1: -30 | F1: mA | G1: NPLC | H1: 20 | I1: ini | J1: 2023 | K1: trecho | L1: 02.txt
B2: Frequency | C2: Data | D2: Points | E2: 1 | F2: thru | G2: 420 | H2: of | I2: 420
B3: Maximum | C3: = | D3: -0.02998571
B4: Minimum | C4: = | D4: -0.02998823
B5: Average | C5: = | D5: -0.02998669
B6: Sigma | C6: Type: | D6: Overlapping | E6: Allan
B7: Confidence | C7: Factor | D7: = | E7: 0.683
B8: Deadtime | C8: T/Tau | D8: = | E8: 1
B10: AF | C10: Tau | D10: # | E10: Alpha | F10: Min | G10: Sigma | H10: Sigma | I10: Max | J10: Sigma
B11: 1 | C11: 1 | D11: 419 | E11: 1 | F11: 0 | G11: 5.9699e-07 | H11: 0
B12: 2 | C12: 2 | D12: 417 | E12: 1 | F12: 0 | G12: 3.5488e-07 | H12: 0
B13: 3 | C13: 3 | D13: 415 | E13: 0 | F13: 0 | G13: 1.8766e-07 | H13: 0
B14: 4 | C14: 4 | D14: 413 | E14: 1 | F14: 0 | G14: 1.809e-07 | H14: 0
B15: 5 | C15: 5 | D15: 411 | E15: 2 | F15: 0 | G15: 1.7523e-07 | H15: 0
B16: 6 | C16: 6 | D16: 409 | E16: 0 | F16: 0 | G16: 1.2465e-07 | H16: 0
B17: 7 | C17: 7 | D17: 407 | E17: 0 | F17: 0 | G17: 8.8365e-08 | H17: 0
B18: 8 | C18: 8 | D18: 405 | E18: 1 | F18: 0 | G18: 1.0126e-07 | H18: 0
B19: 9 | C19: 9 | D19: 403 | E19: 0 | F19: 0 | G19: 8.8418e-08 | H19: 0
B20: 10 | C20: 10 | D20: 401 | E20: 0 | F20: 0 | G20: 6.555e-08 | H20: 0
B21: 11 | C21: 11 | D21: 399 | E21: 0 | F21: 0 | G21: 7.6307e-08 | H21: 0
B22: 12 | C22: 12 | D22: 397 | E22: 0 | F22: 0 | G22: 7.4947e-08 | H22: 0
... B97: 103 | C97: 103 | D97: 215 | E97: 0 | F97: 0 | G97: 4.3615e-08 | H97: 0

Sheet Plan18
B1: STATISTICS | C1: FOR | D1: FILE: | E1: -30 | F1: mA | G1: NPLC | H1: 20 | I1: ini | J1: 2023 | K1: trecho | L1: 03.txt
B2: Frequency | C2: Data | D2: Points | E2: 1 | F2: thru | G2: 419 | H2: of | I2: 419
B3: Maximum | C3: = | D3: -0.02998573
B4: Minimum | C4: = | D4: -0.02998827
B5: Average | C5: = | D5: -0.0299867
B6: Sigma | C6: Type: | D6: Overlapping | E6: Allan
B7: Confidence | C7: Factor | D7: = | E7: 0.683
B8: Deadtime | C8: T/Tau | D8: = | E8: 1
B10: AF | C10: Tau | D10: # | E10: Alpha | F10: Min | G10: Sigma | H10: Sigma | I10: Max | J10: Sigma
B11: 1 | C11: 1 | D11: 418 | E11: 1 | F11: 0 | G11: 6.183e-07 | H11: 0
B12: 2 | C12: 2 | D12: 416 | E12: 1 | F12: 0 | G12: 3.5185e-07 | H12: 0
B13: 3 | C13: 3 | D13: 414 | E13: 0 | F13: 0 | G13: 1.7436e-07 | H13: 0
B14: 4 | C14: 4 | D14: 412 | E14: 0 | F14: 0 | G14: 1.8896e-07 | H14: 0
B15: 5 | C15: 5 | D15: 410 | E15: 1 | F15: 0 | G15: 1.8085e-07 | H15: 0
B16: 6 | C16: 6 | D16: 408 | E16: 0 | F16: 0 | G16: 1.362e-07 | H16: 0
B17: 7 | C17: 7 | D17: 406 | E17: 0 | F17: 0 | G17: 1.1049e-07 | H17: 0
B18: 8 | C18: 8 | D18: 404 | E18: 0 | F18: 0 | G18: 1.1984e-07 | H18: 0
B19: 9 | C19: 9 | D19: 402 | E19: 0 | F19: 0 | G19: 1.0714e-07 | H19: 0
B20: 10 | C20: 10 | D20: 400 | E20: 0 | F20: 0 | G20: 8.701e-08 | H20: 0
B21: 11 | C21: 11 | D21: 398 | E21: 0 | F21: 0 | G21: 9.4083e-08 | H21: 0
B22: 12 | C22: 12 | D22: 396 | E22: 0 | F22: 0 | G22: 9.3215e-08 | H22: 0
... B97: 103 | C97: 103 | D97: 214 | E97: 0 | F97: 0 | G97: 3.0335e-08 | H97: 0

Sheet Plan19
B1: STATISTICS | C1: FOR | D1: FILE: | E1: -30 | F1: mA | G1: NPLC | H1: 20 | I1: ini | J1: 2023 | K1: trecho | L1: 04.txt
B2: Frequency | C2: Data | D2: Points | E2: 1 | F2: thru | G2: 419 | H2: of | I2: 419
B3: Maximum | C3: = | D3: -0.02998582
B4: Minimum | C4: = | D4: -0.02998823
B5: Average | C5: = | D5: -0.02998675
B6: Sigma | C6: Type: | D6: Overlapping | E6: Allan
B7: Confidence | C7: Factor | D7: = | E7: 0.683
B8: Deadtime | C8: T/Tau | D8: = | E8: 1
B10: AF | C10: Tau | D10: # | E10: Alpha | F10: Min | G10: Sigma | H10: Sigma | I10: Max | J10: Sigma
B11: 1 | C11: 1 | D11: 418 | E11: 1 | F11: 0 | G11: 6.0384e-07 | H11: 0
B12: 2 | C12: 2 | D12: 416 | E12: 1 | F12: 0 | G12: 3.5096e-07 | H12: 0
B13: 3 | C13: 3 | D13: 414 | E13: 0 | F13: 0 | G13: 1.7182e-07 | H13: 0
B14: 4 | C14: 4 | D14: 412 | E14: 0 | F14: 0 | G14: 1.8177e-07 | H14: 0
B15: 5 | C15: 5 | D15: 410 | E15: 0 | F15: 0 | G15: 1.7382e-07 | H15: 0
B16: 6 | C16: 6 | D16: 408 | E16: 0 | F16: 0 | G16: 1.3347e-07 | H16: 0
B17: 7 | C17: 7 | D17: 406 | E17: 0 | F17: 0 | G17: 1.1828e-07 | H17: 0
B18: 8 | C18: 8 | D18: 404 | E18: 0 | F18: 0 | G18: 1.1668e-07 | H18: 0
B19: 9 | C19: 9 | D19: 402 | E19: 0 | F19: 0 | G19: 1.0461e-07 | H19: 0
B20: 10 | C20: 10 | D20: 400 | E20: -1 | F20: 0 | G20: 9.2485e-08 | H20: 0
B21: 11 | C21: 11 | D21: 398 | E21: 0 | F21: 0 | G21: 9.0565e-08 | H21: 0
B22: 12 | C22: 12 | D22: 396 | E22: 0 | F22: 0 | G22: 8.6169e-08 | H22: 0
... B97: 103 | C97: 103 | D97: 214 | E97: -1 | F97: 0 | G97: 4.3009e-08 | H97: 0

Sheet Plan20
B1: STATISTICS | C1: FOR | D1: FILE: | E1: -30 | F1: mA | G1: NPLC | H1: 20 | I1: ini | J1: 2023 | K1: trecho | L1: 05.txt
B2: Frequency | C2: Data | D2: Points | E2: 1 | F2: thru | G2: 419 | H2: of | I2: 419
B3: Maximum | C3: = | D3: -0.02998583
B4: Minimum | C4: = | D4: -0.02998832
B5: Average | C5: = | D5: -0.02998677
B6: Sigma | C6: Type: | D6: Overlapping | E6: Allan
B7: Confidence | C7: Factor | D7: = | E7: 0.683
B8: Deadtime | C8: T/Tau | D8: = | E8: 1
B10: AF | C10: Tau | D10: # | E10: Alpha | F10: Min | G10: Sigma | H10: Sigma | I10: Max | J10: Sigma
B11: 1 | C11: 1 | D11: 418 | E11: 1 | F11: 0 | G11: 5.8292e-07 | H11: 0
B12: 2 | C12: 2 | D12: 416 | E12: 1 | F12: 0 | G12: 3.3902e-07 | H12: 0
B13: 3 | C13: 3 | D13: 414 | E13: 0 | F13: 0 | G13: 1.6717e-07 | H13: 0
B14: 4 | C14: 4 | D14: 412 | E14: 0 | F14: 0 | G14: 1.7744e-07 | H14: 0
B15: 5 | C15: 5 | D15: 410 | E15: 1 | F15: 0 | G15: 1.7579e-07 | H15: 0
B16: 6 | C16: 6 | D16: 408 | E16: 0 | F16: 0 | G16: 1.3364e-07 | H16: 0
B17: 7 | C17: 7 | D17: 406 | E17: 0 | F17: 0 | G17: 1.1329e-07 | H17: 0
B18: 8 | C18: 8 | D18: 404 | E18: 0 | F18: 0 | G18: 1.2133e-07 | H18: 0
B19: 9 | C19: 9 | D19: 402 | E19: 1 | F19: 0 | G19: 1.071e-07 | H19: 0
B20: 10 | C20: 10 | D20: 400 | E20: 0 | F20: 0 | G20: 8.9442e-08 | H20: 0
B21: 11 | C21: 11 | D21: 398 | E21: 0 | F21: 0 | G21: 9.164e-08 | H21: 0
B22: 12 | C22: 12 | D22: 396 | E22: 0 | F22: 0 | G22: 8.5001e-08 | H22: 0
... B97: 103 | C97: 103 | D97: 214 | E97: -1 | F97: 0 | G97: 3.3646e-08 | H97: 0

Sheet 10 mA
A1: Tempo (s) | B1: Trecho 1 | C1: Trecho 2 | D1: Trecho 3 | E1: Trecho 4 | F1: Trecho 5 | G1: Trecho 6 | H1: Trecho 7 | I1: Trecho 8 | J1: Trecho 9 | K1: Trecho 10 | L1: MÉDIA | M1: Min. (A) | N1: Max. (A) | O1: Intervalo de confiança (t-Student, 95 %) | P1: Iq (ruído de quant., em A) --> | Q1: =0.000000001*12^(-0.5) -> 2.8867513e-10 | R1: Resol. (em A) --> | S1: 1e-09
A2: 1 | B2: ='Plan11 (2)'!$G11 -> 6.0903e-08 | C2: ='Plan12 (2)'!$G11 -> 6.4708e-08 | D2: ='Plan13 (2)'!$G11 -> 6.7923e-08 | E2: ='Plan14 (2)'!$G11 -> 6.4501e-08 | F2: ='Plan15 (2)'!$G11 -> 6.5133e-08 | G2: ='Plan16 (2)'!$G11 -> 5.8729e-08 | H2: ='Plan17 (2)'!$G11 -> 6.0543e-08 | I2: ='Plan18 (2)'!$G11 -> 6.117e-08 | J2: ='Plan19 (2)'!$G11 -> 6.0597e-08 | K2: ='Plan20 (2)'!$G11 -> 6.2845e-08 | L2: =AVERAGE(B2:K2) -> 6.27052e-08 | M2: =L2-O2 -> 6.0697241e-08 | N2: =L2+O2 -> 6.4713159e-08 | O2: =_xlfn.CONFIDENCE.T(0.05,_xlfn.STDEV.S(B2:K2),COUNTA(B2:K2)) -> 2.0079588e-09
A3: 2 | B3: ='Plan11 (2)'!$G12 -> 3.1096e-08 | C3: ='Plan12 (2)'!$G12 -> 2.7973e-08 | D3: ='Plan13 (2)'!$G12 -> 3.1598e-08 | E3: ='Plan14 (2)'!$G12 -> 2.6584e-08 | F3: ='Plan15 (2)'!$G12 -> 2.7626e-08 | G3: ='Plan16 (2)'!$G12 -> 2.8841e-08 | H3: ='Plan17 (2)'!$G12 -> 2.8039e-08 | I3: ='Plan18 (2)'!$G12 -> 2.7196e-08 | J3: ='Plan19 (2)'!$G12 -> 2.7555e-08 | K3: ='Plan20 (2)'!$G12 -> 2.5024e-08 | L3: =AVERAGE(B3:K3) -> 2.81532e-08 | M3: =L3-O3 -> 2.6745491e-08 | N3: =L3+O3 -> 2.9560909e-08 | O3: =_xlfn.CONFIDENCE.T(0.05,_xlfn.STDEV.S(B3:K3),COUNTA(B3:K3)) -> 1.4077089e-09
A4: 3 | B4: ='Plan11 (2)'!$G13 -> 1.8173e-08 | C4: ='Plan12 (2)'!$G13 -> 1.7235e-08 | D4: ='Plan13 (2)'!$G13 -> 2.0841e-08 | E4: ='Plan14 (2)'!$G13 -> 2.0964e-08 | F4: ='Plan15 (2)'!$G13 -> 2.4233e-08 | G4: ='Plan16 (2)'!$G13 -> 1.7487e-08 | H4: ='Plan17 (2)'!$G13 -> 1.9119e-08 | I4: ='Plan18 (2)'!$G13 -> 1.809e-08 | J4: ='Plan19 (2)'!$G13 -> 2.0728e-08 | K4: ='Plan20 (2)'!$G13 -> 2.1692e-08 | L4: =AVERAGE(B4:K4) -> 1.98562e-08 | M4: =L4-O4 -> 1.8266177e-08 | N4: =L4+O4 -> 2.1446223e-08 | O4: =_xlfn.CONFIDENCE.T(0.05,_xlfn.STDEV.S(B4:K4),COUNTA(B4:K4)) -> 1.590023e-09
A5: 4 | B5: ='Plan11 (2)'!$G14 -> 2.2067e-08 | C5: ='Plan12 (2)'!$G14 -> 2.1315e-08 | D5: ='Plan13 (2)'!$G14 -> 2.4512e-08 | E5: ='Plan14 (2)'!$G14 -> 2.0086e-08 | F5: ='Plan15 (2)'!$G14 -> 2.2026e-08 | G5: ='Plan16 (2)'!$G14 -> 2.1024e-08 | H5: ='Plan17 (2)'!$G14 -> 2.1468e-08 | I5: ='Plan18 (2)'!$G14 -> 2.0582e-08 | J5: ='Plan19 (2)'!$G14 -> 2.1195e-08 | K5: ='Plan20 (2)'!$G14 -> 1.8051e-08 | L5: =AVERAGE(B5:K5) -> 2.12326e-08 | M5: =L5-O5 -> 2.0063263e-08 | N5: =L5+O5 -> 2.2401937e-08 | O5: =_xlfn.CONFIDENCE.T(0.05,_xlfn.STDEV.S(B5:K5),COUNTA(B5:K5)) -> 1.1693369e-09
A6: 5 | B6: ='Plan11 (2)'!$G15 -> 1.7495e-08 | C6: ='Plan12 (2)'!$G15 -> 1.478e-08 | D6: ='Plan13 (2)'!$G15 -> 1.8464e-08 | E6: ='Plan14 (2)'!$G15 -> 1.6343e-08 | F6: ='Plan15 (2)'!$G15 -> 1.894e-08 | G6: ='Plan16 (2)'!$G15 -> 1.749e-08 | H6: ='Plan17 (2)'!$G15 -> 1.5447e-08 | I6: ='Plan18 (2)'!$G15 -> 1.5307e-08 | J6: ='Plan19 (2)'!$G15 -> 1.5953e-08 | K6: ='Plan20 (2)'!$G15 -> 1.6457e-08 | L6: =AVERAGE(B6:K6) -> 1.66676e-08 | M6: =L6-O6 -> 1.5675332e-08 | N6: =L6+O6 -> 1.7659868e-08 | O6: =_xlfn.CONFIDENCE.T(0.05,_xlfn.STDEV.S(B6:K6),COUNTA(B6:K6)) -> 9.9226786e-10
A7: 6 | B7: ='Plan11 (2)'!$G16 -> 1.3979e-08 | C7: ='Plan12 (2)'!$G16 -> 1.3939e-08 | D7: ='Plan13 (2)'!$G16 -> 1.705e-08 | E7: ='Plan14 (2)'!$G16 -> 1.7064e-08 | F7: ='Plan15 (2)'!$G16 -> 1.874e-08 | G7: ='Plan16 (2)'!$G16 -> 1.6259e-08 | H7: ='Plan17 (2)'!$G16 -> 1.385e-08 | I7: ='Plan18 (2)'!$G16 -> 1.4357e-08 | J7: ='Plan19 (2)'!$G16 -> 1.5724e-08 | K7: ='Plan20 (2)'!$G16 -> 1.4996e-08 | L7: =AVERAGE(B7:K7) -> 1.55958e-08 | M7: =L7-O7 -> 1.4405596e-08 | N7: =L7+O7 -> 1.6786004e-08 | O7: =_xlfn.CONFIDENCE.T(0.05,_xlfn.STDEV.S(B7:K7),COUNTA(B7:K7)) -> 1.1902044e-09
A8: 7 | B8: ='Plan11 (2)'!$G17 -> 1.4248e-08 | C8: ='Plan12 (2)'!$G17 -> 1.4264e-08 | D8: ='Plan13 (2)'!$G17 -> 1.6946e-08 | E8: ='Plan14 (2)'!$G17 -> 1.4317e-08 | F8: ='Plan15 (2)'!$G17 -> 1.5915e-08 | G8: ='Plan16 (2)'!$G17 -> 1.7487e-08 | H8: ='Plan17 (2)'!$G17 -> 1.3097e-08 | I8: ='Plan18 (2)'!$G17 -> 1.3277e-08 | J8: ='Plan19 (2)'!$G17 -> 1.3815e-08 | K8: ='Plan20 (2)'!$G17 -> 1.2681e-08 | L8: =AVERAGE(B8:K8) -> 1.46047e-08 | M8: =L8-O8 -> 1.3431852e-08 | N8: =L8+O8 -> 1.5777548e-08 | O8: =_xlfn.CONFIDENCE.T(0.05,_xlfn.STDEV.S(B8:K8),COUNTA(B8:K8)) -> 1.1728485e-09
A9: 8 | B9: ='Plan11 (2)'!$G18 -> 1.2145e-08 | C9: ='Plan12 (2)'!$G18 -> 1.2475e-08 | D9: ='Plan13 (2)'!$G18 -> 1.5541e-08 | E9: ='Plan14 (2)'!$G18 -> 1.4862e-08 | F9: ='Plan15 (2)'!$G18 -> 1.6902e-08 | G9: ='Plan16 (2)'!$G18 -> 1.6869e-08 | H9: ='Plan17 (2)'!$G18 -> 1.1137e-08 | I9: ='Plan18 (2)'!$G18 -> 1.2157e-08 | J9: ='Plan19 (2)'!$G18 -> 1.3962e-08 | K9: ='Plan20 (2)'!$G18 -> 1.3219e-08 | L9: =AVERAGE(B9:K9) -> 1.39269e-08 | M9: =L9-O9 -> 1.2463018e-08 | N9: =L9+O9 -> 1.5390782e-08 | O9: =_xlfn.CONFIDENCE.T(0.05,_xlfn.STDEV.S(B9:K9),COUNTA(B9:K9)) -> 1.4638821e-09
A10: 9 | B10: ='Plan11 (2)'!$G19 -> 1.1102e-08 | C10: ='Plan12 (2)'!$G19 -> 1.2948e-08 | D10: ='Plan13 (2)'!$G19 -> 1.6296e-08 | E10: ='Plan14 (2)'!$G19 -> 1.4096e-08 | F10: ='Plan15 (2)'!$G19 -> 1.5839e-08 | G10: ='Plan16 (2)'!$G19 -> 1.716e-08 | H10: ='Plan17 (2)'!$G19 -> 1.1273e-08 | I10: ='Plan18 (2)'!$G19 -> 1.1961e-08 | J10: ='Plan19 (2)'!$G19 -> 1.434e-08 | K10: ='Plan20 (2)'!$G19 -> 1.1623e-08 | L10: =AVERAGE(B10:K10) -> 1.36638e-08 | M10: =L10-O10 -> 1.2075218e-08 | N10: =L10+O10 -> 1.5252382e-08 | O10: =_xlfn.CONFIDENCE.T(0.05,_xlfn.STDEV.S(B10:K10),COUNTA(B10:K10)) -> 1.5885816e-09
A11: 10 | B11: ='Plan11 (2)'!$G20 -> 1.1556e-08 | C11: ='Plan12 (2)'!$G20 -> 1.2452e-08 | D11: ='Plan13 (2)'!$G20 -> 1.6562e-08 | E11: ='Plan14 (2)'!$G20 -> 1.3241e-08 | F11: ='Plan15 (2)'!$G20 -> 1.5736e-08 | G11: ='Plan16 (2)'!$G20 -> 1.7891e-08 | H11: ='Plan17 (2)'!$G20 -> 1.0233e-08 | I11: ='Plan18 (2)'!$G20 -> 1.095e-08 | J11: ='Plan19 (2)'!$G20 -> 1.3587e-08 | K11: ='Plan20 (2)'!$G20 -> 1.1746e-08 | L11: =AVERAGE(B11:K11) -> 1.33954e-08 | M11: =L11-O11 -> 1.1567676e-08 | N11: =L11+O11 -> 1.5223124e-08 | O11: =_xlfn.CONFIDENCE.T(0.05,_xlfn.STDEV.S(B11:K11),COUNTA(B11:K11)) -> 1.8277241e-09
A12: 11 | B12: ='Plan11 (2)'!$G21 -> 1.0871e-08 | C12: ='Plan12 (2)'!$G21 -> 1.2156e-08 | D12: ='Plan13 (2)'!$G21 -> 1.6749e-08 | E12: ='Plan14 (2)'!$G21 -> 1.3108e-08 | F12: ='Plan15 (2)'!$G21 -> 1.5939e-08 | G12: ='Plan16 (2)'!$G21 -> 1.8204e-08 | H12: ='Plan17 (2)'!$G21 -> 1.0049e-08 | I12: ='Plan18 (2)'!$G21 -> 1.0937e-08 | J12: ='Plan19 (2)'!$G21 -> 1.4273e-08 | K12: ='Plan20 (2)'!$G21 -> 1.1271e-08 | L12: =AVERAGE(B12:K12) -> 1.33557e-08 | M12: =L12-O12 -> 1.1341659e-08 | N12: =L12+O12 -> 1.5369741e-08 | O12: =_xlfn.CONFIDENCE.T(0.05,_xlfn.STDEV.S(B12:K12),COUNTA(B12:K12)) -> 2.0140412e-09
A13: 12 | B13: ='Plan11 (2)'!$G22 -> 1.0799e-08 | C13: ='Plan12 (2)'!$G22 -> 1.2518e-08 | D13: ='Plan13 (2)'!$G22 -> 1.758e-08 | E13: ='Plan14 (2)'!$G22 -> 1.2341e-08 | F13: ='Plan15 (2)'!$G22 -> 1.5827e-08 | G13: ='Plan16 (2)'!$G22 -> 1.8892e-08 | H13: ='Plan17 (2)'!$G22 -> 1.049e-08 | I13: ='Plan18 (2)'!$G22 -> 1.0828e-08 | J13: ='Plan19 (2)'!$G22 -> 1.4355e-08 | K13: ='Plan20 (2)'!$G22 -> 1.1463e-08 | L13: =AVERAGE(B13:K13) -> 1.35093e-08 | M13: =L13-O13 -> 1.1352431e-08 | N13: =L13+O13 -> 1.5666169e-08 | O13: =_xlfn.CONFIDENCE.T(0.05,_xlfn.STDEV.S(B13:K13),COUNTA(B13:K13)) -> 2.1568694e-09
... A88: 103 | B88: ='Plan11 (2)'!$G97 -> 6.4563e-09 | C88: ='Plan12 (2)'!$G97 -> 1.55e-08 | D88: ='Plan13 (2)'!$G97 -> 2.3239e-08 | E88: ='Plan14 (2)'!$G97 -> 1.8542e-08 | F88: ='Plan15 (2)'!$G97 -> 1.7771e-08 | G88: ='Plan16 (2)'!$G97 -> 2.6958e-08 | H88: ='Plan17 (2)'!$G97 -> 2.2496e-08 | I88: ='Plan18 (2)'!$G97 -> 1.8982e-08 | J88: ='Plan19 (2)'!$G97 -> 2.476e-08 | K88: ='Plan20 (2)'!$G97 -> 2.0709e-08 | L88: =AVERAGE(B88:K88) -> 1.954133e-08 | M88: =L88-O88 -> 1.5424979e-08 | N88: =L88+O88 -> 2.3657681e-08 | O88: =_xlfn.CONFIDENCE.T(0.05,_xlfn.STDEV.S(B88:K88),COUNTA(B88:K88)) -> 4.1163508e-09

Sheet Plan11 (2)
B1: STATISTICS | C1: FOR | D1: FILE: | E1: 10 | F1: mA | G1: NPLC | H1: 20 | I1: ini | J1: 2023 | K1: trecho | L1: 01.txt
B2: Frequency | C2: Data | D2: Points | E2: 1 | F2: thru | G2: 423 | H2: of | I2: 423
B3: Maximum | C3: = | D3: 0.01000135
B4: Minimum | C4: = | D4: 0.01000106
B5: Average | C5: = | D5: 0.0100012
B6: Sigma | C6: Type: | D6: Overlapping | E6: Allan
B7: Confidence | C7: Factor | D7: = | E7: 0.683
B8: Deadtime | C8: T/Tau | D8: = | E8: 1
B10: AF | C10: Tau | D10: # | E10: Alpha | F10: Min | G10: Sigma | H10: Sigma | I10: Max | J10: Sigma
B11: 1 | C11: 1 | D11: 422 | E11: 1 | F11: 0 | G11: 6.0903e-08 | H11: 0
B12: 2 | C12: 2 | D12: 420 | E12: 0 | F12: 0 | G12: 3.1096e-08 | H12: 0
B13: 3 | C13: 3 | D13: 418 | E13: 0 | F13: 0 | G13: 1.8173e-08 | H13: 0
B14: 4 | C14: 4 | D14: 416 | E14: 0 | F14: 0 | G14: 2.2067e-08 | H14: 0
B15: 5 | C15: 5 | D15: 414 | E15: -1 | F15: 0 | G15: 1.7495e-08 | H15: 0
B16: 6 | C16: 6 | D16: 412 | E16: 0 | F16: 0 | G16: 1.3979e-08 | H16: 0
B17: 7 | C17: 7 | D17: 410 | E17: 0 | F17: 0 | G17: 1.4248e-08 | H17: 0
B18: 8 | C18: 8 | D18: 408 | E18: -1 | F18: 0 | G18: 1.2145e-08 | H18: 0
B19: 9 | C19: 9 | D19: 406 | E19: 0 | F19: 0 | G19: 1.1102e-08 | H19: 0
B20: 10 | C20: 10 | D20: 404 | E20: -1 | F20: 0 | G20: 1.1556e-08 | H20: 0
B21: 11 | C21: 11 | D21: 402 | E21: -1 | F21: 0 | G21: 1.0871e-08 | H21: 0
B22: 12 | C22: 12 | D22: 400 | E22: -1 | F22: 0 | G22: 1.0799e-08 | H22: 0
... B97: 103 | C97: 103 | D97: 218 | E97: -1 | F97: 0 | G97: 6.4563e-09 | H97: 0

Sheet Plan12 (2)
B1: STATISTICS | C1: FOR | D1: FILE: | E1: 10 | F1: mA | G1: NPLC | H1: 20 | I1: ini | J1: 2023 | K1: trecho | L1: 02.txt
B2: Frequency | C2: Data | D2: Points | E2: 1 | F2: thru | G2: 419 | H2: of | I2: 419
B3: Maximum | C3: = | D3: 0.01000148
B4: Minimum | C4: = | D4: 0.0100011
B5: Average | C5: = | D5: 0.01000126
B6: Sigma | C6: Type: | D6: Overlapping | E6: Allan
B7: Confidence | C7: Factor | D7: = | E7: 0.683
B8: Deadtime | C8: T/Tau | D8: = | E8: 1
B10: AF | C10: Tau | D10: # | E10: Alpha | F10: Min | G10: Sigma | H10: Sigma | I10: Max | J10: Sigma
B11: 1 | C11: 1 | D11: 418 | E11: 0 | F11: 0 | G11: 6.4708e-08 | H11: 0
B12: 2 | C12: 2 | D12: 416 | E12: 0 | F12: 0 | G12: 2.7973e-08 | H12: 0
B13: 3 | C13: 3 | D13: 414 | E13: 0 | F13: 0 | G13: 1.7235e-08 | H13: 0
B14: 4 | C14: 4 | D14: 412 | E14: 1 | F14: 0 | G14: 2.1315e-08 | H14: 0
B15: 5 | C15: 5 | D15: 410 | E15: -1 | F15: 0 | G15: 1.478e-08 | H15: 0
B16: 6 | C16: 6 | D16: 408 | E16: -1 | F16: 0 | G16: 1.3939e-08 | H16: 0
B17: 7 | C17: 7 | D17: 406 | E17: -1 | F17: 0 | G17: 1.4264e-08 | H17: 0
B18: 8 | C18: 8 | D18: 404 | E18: -2 | F18: 0 | G18: 1.2475e-08 | H18: 0
B19: 9 | C19: 9 | D19: 402 | E19: -1 | F19: 0 | G19: 1.2948e-08 | H19: 0
B20: 10 | C20: 10 | D20: 400 | E20: -1 | F20: 0 | G20: 1.2452e-08 | H20: 0
B21: 11 | C21: 11 | D21: 398 | E21: -2 | F21: 0 | G21: 1.2156e-08 | H21: 0
B22: 12 | C22: 12 | D22: 396 | E22: -2 | F22: 0 | G22: 1.2518e-08 | H22: 0
... B97: 103 | C97: 103 | D97: 214 | E97: -1 | F97: 0 | G97: 1.55e-08 | H97: 0

Sheet Plan13 (2)
B1: STATISTICS | C1: FOR | D1: FILE: | E1: 10 | F1: mA | G1: NPLC | H1: 20 | I1: ini | J1: 2023 | K1: trecho | L1: 03.txt
B2: Frequency | C2: Data | D2: Points | E2: 1 | F2: thru | G2: 419 | H2: of | I2: 419
B3: Maximum | C3: = | D3: 0.01000157
B4: Minimum | C4: = | D4: 0.01000111
B5: Average | C5: = | D5: 0.01000128
B6: Sigma | C6: Type: | D6: Overlapping | E6: Allan
B7: Confidence | C7: Factor | D7: = | E7: 0.683
B8: Deadtime | C8: T/Tau | D8: = | E8: 1
B10: AF | C10: Tau | D10: # | E10: Alpha | F10: Min | G10: Sigma | H10: Sigma | I10: Max | J10: Sigma
B11: 1 | C11: 1 | D11: 418 | E11: 0 | F11: 0 | G11: 6.7923e-08 | H11: 0
B12: 2 | C12: 2 | D12: 416 | E12: -1 | F12: 0 | G12: 3.1598e-08 | H12: 0
B13: 3 | C13: 3 | D13: 414 | E13: -1 | F13: 0 | G13: 2.0841e-08 | H13: 0
B14: 4 | C14: 4 | D14: 412 | E14: 2 | F14: 0 | G14: 2.4512e-08 | H14: 0
B15: 5 | C15: 5 | D15: 410 | E15: -1 | F15: 0 | G15: 1.8464e-08 | H15: 0
B16: 6 | C16: 6 | D16: 408 | E16: -1 | F16: 0 | G16: 1.705e-08 | H16: 0
B17: 7 | C17: 7 | D17: 406 | E17: -1 | F17: 0 | G17: 1.6946e-08 | H17: 0
B18: 8 | C18: 8 | D18: 404 | E18: -2 | F18: 0 | G18: 1.5541e-08 | H18: 0
B19: 9 | C19: 9 | D19: 402 | E19: -2 | F19: 0 | G19: 1.6296e-08 | H19: 0
B20: 10 | C20: 10 | D20: 400 | E20: -2 | F20: 0 | G20: 1.6562e-08 | H20: 0
B21: 11 | C21: 11 | D21: 398 | E21: -2 | F21: 0 | G21: 1.6749e-08 | H21: 0
B22: 12 | C22: 12 | D22: 396 | E22: -2 | F22: 0 | G22: 1.758e-08 | H22: 0
... B97: 103 | C97: 103 | D97: 214 | E97: -1 | F97: 0 | G97: 2.3239e-08 | H97: 0

Sheet Plan14 (2)
B1: STATISTICS | C1: FOR | D1: FILE: | E1: 10 | F1: mA | G1: NPLC | H1: 20 | I1: ini | J1: 2023 | K1: trecho | L1: 04.txt
B2: Frequency | C2: Data | D2: Points | E2: 1 | F2: thru | G2: 420 | H2: of | I2: 420
B3: Maximum | C3: = | D3: 0.01000162
B4: Minimum | C4: = | D4: 0.01000115
B5: Average | C5: = | D5: 0.01000129
B6: Sigma | C6: Type: | D6: Overlapping | E6: Allan
B7: Confidence | C7: Factor | D7: = | E7: 0.683
B8: Deadtime | C8: T/Tau | D8: = | E8: 1
B10: AF | C10: Tau | D10: # | E10: Alpha | F10: Min | G10: Sigma | H10: Sigma | I10: Max | J10: Sigma
B11: 1 | C11: 1 | D11: 419 | E11: 0 | F11: 0 | G11: 6.4501e-08 | H11: 0
B12: 2 | C12: 2 | D12: 417 | E12: -1 | F12: 0 | G12: 2.6584e-08 | H12: 0
B13: 3 | C13: 3 | D13: 415 | E13: -1 | F13: 0 | G13: 2.0964e-08 | H13: 0
B14: 4 | C14: 4 | D14: 413 | E14: 0 | F14: 0 | G14: 2.0086e-08 | H14: 0
B15: 5 | C15: 5 | D15: 411 | E15: -1 | F15: 0 | G15: 1.6343e-08 | H15: 0
B16: 6 | C16: 6 | D16: 409 | E16: -1 | F16: 0 | G16: 1.7064e-08 | H16: 0
B17: 7 | C17: 7 | D17: 407 | E17: -1 | F17: 0 | G17: 1.4317e-08 | H17: 0
B18: 8 | C18: 8 | D18: 405 | E18: -1 | F18: 0 | G18: 1.4862e-08 | H18: 0
B19: 9 | C19: 9 | D19: 403 | E19: 0 | F19: 0 | G19: 1.4096e-08 | H19: 0
B20: 10 | C20: 10 | D20: 401 | E20: -1 | F20: 0 | G20: 1.3241e-08 | H20: 0
B21: 11 | C21: 11 | D21: 399 | E21: -2 | F21: 0 | G21: 1.3108e-08 | H21: 0
B22: 12 | C22: 12 | D22: 397 | E22: -2 | F22: 0 | G22: 1.2341e-08 | H22: 0
... B97: 103 | C97: 103 | D97: 215 | E97: -1 | F97: 0 | G97: 1.8542e-08 | H97: 0

Sheet Plan15 (2)
B1: STATISTICS | C1: FOR | D1: FILE: | E1: 10 | F1: mA | G1: NPLC | H1: 20 | I1: ini | J1: 2023 | K1: trecho | L1: 05.txt
B2: Frequency | C2: Data | D2: Points | E2: 1 | F2: thru | G2: 420 | H2: of | I2: 420
B3: Maximum | C3: = | D3: 0.01000159
B4: Minimum | C4: = | D4: 0.0100011
B5: Average | C5: = | D5: 0.01000131
B6: Sigma | C6: Type: | D6: Overlapping | E6: Allan
B7: Confidence | C7: Factor | D7: = | E7: 0.683
B8: Deadtime | C8: T/Tau | D8: = | E8: 1
B10: AF | C10: Tau | D10: # | E10: Alpha | F10: Min | G10: Sigma | H10: Sigma | I10: Max | J10: Sigma
B11: 1 | C11: 1 | D11: 419 | E11: 0 | F11: 0 | G11: 6.5133e-08 | H11: 0
B12: 2 | C12: 2 | D12: 417 | E12: 0 | F12: 0 | G12: 2.7626e-08 | H12: 0
B13: 3 | C13: 3 | D13: 415 | E13: -1 | F13: 0 | G13: 2.4233e-08 | H13: 0
B14: 4 | C14: 4 | D14: 413 | E14: -1 | F14: 0 | G14: 2.2026e-08 | H14: 0
B15: 5 | C15: 5 | D15: 411 | E15: -1 | F15: 0 | G15: 1.894e-08 | H15: 0
B16: 6 | C16: 6 | D16: 409 | E16: -1 | F16: 0 | G16: 1.874e-08 | H16: 0
B17: 7 | C17: 7 | D17: 407 | E17: -1 | F17: 0 | G17: 1.5915e-08 | H17: 0
B18: 8 | C18: 8 | D18: 405 | E18: -2 | F18: 0 | G18: 1.6902e-08 | H18: 0
B19: 9 | C19: 9 | D19: 403 | E19: -2 | F19: 0 | G19: 1.5839e-08 | H19: 0
B20: 10 | C20: 10 | D20: 401 | E20: -1 | F20: 0 | G20: 1.5736e-08 | H20: 0
B21: 11 | C21: 11 | D21: 399 | E21: -2 | F21: 0 | G21: 1.5939e-08 | H21: 0
B22: 12 | C22: 12 | D22: 397 | E22: -2 | F22: 0 | G22: 1.5827e-08 | H22: 0
... B97: 103 | C97: 103 | D97: 215 | E97: -1 | F97: 0 | G97: 1.7771e-08 | H97: 0

Sheet Plan16 (2)
B1: STATISTICS | C1: FOR | D1: FILE: | E1: -10 | F1: mA | G1: NPLC | H1: 20 | I1: ini | J1: 2023 | K1: trecho | L1: 01.txt
B2: Frequency | C2: Data | D2: Points | E2: 1 | F2: thru | G2: 419 | H2: of | I2: 419
B3: Maximum | C3: = | D3: -0.009998537
B4: Minimum | C4: = | D4: -0.009998899
B5: Average | C5: = | D5: -0.009998698
B6: Sigma | C6: Type: | D6: Overlapping | E6: Allan
B7: Confidence | C7: Factor | D7: = | E7: 0.683
B8: Deadtime | C8: T/Tau | D8: = | E8: 1
B10: AF | C10: Tau | D10: # | E10: Alpha | F10: Min | G10: Sigma | H10: Sigma | I10: Max | J10: Sigma
B11: 1 | C11: 1 | D11: 418 | E11: 0 | F11: 0 | G11: 5.8729e-08 | H11: 0
B12: 2 | C12: 2 | D12: 416 | E12: 0 | F12: 0 | G12: 2.8841e-08 | H12: 0
B13: 3 | C13: 3 | D13: 414 | E13: -1 | F13: 0 | G13: 1.7487e-08 | H13: 0
B14: 4 | C14: 4 | D14: 412 | E14: -1 | F14: 0 | G14: 2.1024e-08 | H14: 0
B15: 5 | C15: 5 | D15: 410 | E15: -2 | F15: 0 | G15: 1.749e-08 | H15: 0
B16: 6 | C16: 6 | D16: 408 | E16: -2 | F16: 0 | G16: 1.6259e-08 | H16: 0
B17: 7 | C17: 7 | D17: 406 | E17: -2 | F17: 0 | G17: 1.7487e-08 | H17: 0
B18: 8 | C18: 8 | D18: 404 | E18: -2 | F18: 0 | G18: 1.6869e-08 | H18: 0
B19: 9 | C19: 9 | D19: 402 | E19: -2 | F19: 0 | G19: 1.716e-08 | H19: 0
B20: 10 | C20: 10 | D20: 400 | E20: -2 | F20: 0 | G20: 1.7891e-08 | H20: 0
B21: 11 | C21: 11 | D21: 398 | E21: -2 | F21: 0 | G21: 1.8204e-08 | H21: 0
B22: 12 | C22: 12 | D22: 396 | E22: -2 | F22: 0 | G22: 1.8892e-08 | H22: 0
... B97: 103 | C97: 103 | D97: 214 | E97: 0 | F97: 0 | G97: 2.6958e-08 | H97: 0

Sheet Plan17 (2)
B1: STATISTICS | C1: FOR | D1: FILE: | E1: -10 | F1: mA | G1: NPLC | H1: 20 | I1: ini | J1: 2023 | K1: trecho | L1: 02.txt
B2: Frequency | C2: Data | D2: Points | E2: 1 | F2: thru | G2: 419 | H2: of | I2: 419
B3: Maximum | C3: = | D3: -0.009998474
B4: Minimum | C4: = | D4: -0.009998918
B5: Average | C5: = | D5: -0.009998664
B6: Sigma | C6: Type: | D6: Overlapping | E6: Allan
B7: Confidence | C7: Factor | D7: = | E7: 0.683
B8: Deadtime | C8: T/Tau | D8: = | E8: 1
B10: AF | C10: Tau | D10: # | E10: Alpha | F10: Min | G10: Sigma | H10: Sigma | I10: Max | J10: Sigma
B11: 1 | C11: 1 | D11: 418 | E11: 0 | F11: 0 | G11: 6.0543e-08 | H11: 0
B12: 2 | C12: 2 | D12: 416 | E12: -1 | F12: 0 | G12: 2.8039e-08 | H12: 0
B13: 3 | C13: 3 | D13: 414 | E13: 0 | F13: 0 | G13: 1.9119e-08 | H13: 0
B14: 4 | C14: 4 | D14: 412 | E14: 2 | F14: 0 | G14: 2.1468e-08 | H14: 0
B15: 5 | C15: 5 | D15: 410 | E15: 0 | F15: 0 | G15: 1.5447e-08 | H15: 0
B16: 6 | C16: 6 | D16: 408 | E16: -1 | F16: 0 | G16: 1.385e-08 | H16: 0
B17: 7 | C17: 7 | D17: 406 | E17: 1 | F17: 0 | G17: 1.3097e-08 | H17: 0
B18: 8 | C18: 8 | D18: 404 | E18: -1 | F18: 0 | G18: 1.1137e-08 | H18: 0
B19: 9 | C19: 9 | D19: 402 | E19: -1 | F19: 0 | G19: 1.1273e-08 | H19: 0
B20: 10 | C20: 10 | D20: 400 | E20: -1 | F20: 0 | G20: 1.0233e-08 | H20: 0
B21: 11 | C21: 11 | D21: 398 | E21: -2 | F21: 0 | G21: 1.0049e-08 | H21: 0
B22: 12 | C22: 12 | D22: 396 | E22: -1 | F22: 0 | G22: 1.049e-08 | H22: 0
... B97: 103 | C97: 103 | D97: 214 | E97: -1 | F97: 0 | G97: 2.2496e-08 | H97: 0

Sheet Plan18 (2)
B1: STATISTICS | C1: FOR | D1: FILE: | E1: -10 | F1: mA | G1: NPLC | H1: 20 | I1: ini | J1: 2023 | K1: trecho | L1: 03.txt
B2: Frequency | C2: Data | D2: Points | E2: 1 | F2: thru | G2: 420 | H2: of | I2: 420
B3: Maximum | C3: = | D3: -0.009998467
B4: Minimum | C4: = | D4: -0.009998911
B5: Average | C5: = | D5: -0.009998651
B6: Sigma | C6: Type: | D6: Overlapping | E6: Allan
B7: Confidence | C7: Factor | D7: = | E7: 0.683
B8: Deadtime | C8: T/Tau | D8: = | E8: 1
B10: AF | C10: Tau | D10: # | E10: Alpha | F10: Min | G10: Sigma | H10: Sigma | I10: Max | J10: Sigma
B11: 1 | C11: 1 | D11: 419 | E11: 0 | F11: 0 | G11: 6.117e-08 | H11: 0
B12: 2 | C12: 2 | D12: 417 | E12: -1 | F12: 0 | G12: 2.7196e-08 | H12: 0
B13: 3 | C13: 3 | D13: 415 | E13: -1 | F13: 0 | G13: 1.809e-08 | H13: 0
B14: 4 | C14: 4 | D14: 413 | E14: 2 | F14: 0 | G14: 2.0582e-08 | H14: 0
B15: 5 | C15: 5 | D15: 411 | E15: -1 | F15: 0 | G15: 1.5307e-08 | H15: 0
B16: 6 | C16: 6 | D16: 409 | E16: -1 | F16: 0 | G16: 1.4357e-08 | H16: 0
B17: 7 | C17: 7 | D17: 407 | E17: 0 | F17: 0 | G17: 1.3277e-08 | H17: 0
B18: 8 | C18: 8 | D18: 405 | E18: -1 | F18: 0 | G18: 1.2157e-08 | H18: 0
B19: 9 | C19: 9 | D19: 403 | E19: -1 | F19: 0 | G19: 1.1961e-08 | H19: 0
B20: 10 | C20: 10 | D20: 401 | E20: -1 | F20: 0 | G20: 1.095e-08 | H20: 0
B21: 11 | C21: 11 | D21: 399 | E21: -1 | F21: 0 | G21: 1.0937e-08 | H21: 0
B22: 12 | C22: 12 | D22: 397 | E22: -2 | F22: 0 | G22: 1.0828e-08 | H22: 0
... B97: 103 | C97: 103 | D97: 215 | E97: -1 | F97: 0 | G97: 1.8982e-08 | H97: 0

Sheet Plan19 (2)
B1: STATISTICS | C1: FOR | D1: FILE: | E1: -10 | F1: mA | G1: NPLC | H1: 20 | I1: ini | J1: 2023 | K1: trecho | L1: 04.txt
B2: Frequency | C2: Data | D2: Points | E2: 1 | F2: thru | G2: 419 | H2: of | I2: 419
B3: Maximum | C3: = | D3: -0.009998472
B4: Minimum | C4: = | D4: -0.009998861
B5: Average | C5: = | D5: -0.009998653
B6: Sigma | C6: Type: | D6: Overlapping | E6: Allan
B7: Confidence | C7: Factor | D7: = | E7: 0.683
B8: Deadtime | C8: T/Tau | D8: = | E8: 1
B10: AF | C10: Tau | D10: # | E10: Alpha | F10: Min | G10: Sigma | H10: Sigma | I10: Max | J10: Sigma
B11: 1 | C11: 1 | D11: 418 | E11: 0 | F11: 0 | G11: 6.0597e-08 | H11: 0
B12: 2 | C12: 2 | D12: 416 | E12: 0 | F12: 0 | G12: 2.7555e-08 | H12: 0
B13: 3 | C13: 3 | D13: 414 | E13: 0 | F13: 0 | G13: 2.0728e-08 | H13: 0
B14: 4 | C14: 4 | D14: 412 | E14: 1 | F14: 0 | G14: 2.1195e-08 | H14: 0
B15: 5 | C15: 5 | D15: 410 | E15: -1 | F15: 0 | G15: 1.5953e-08 | H15: 0
B16: 6 | C16: 6 | D16: 408 | E16: -1 | F16: 0 | G16: 1.5724e-08 | H16: 0
B17: 7 | C17: 7 | D17: 406 | E17: -1 | F17: 0 | G17: 1.3815e-08 | H17: 0
B18: 8 | C18: 8 | D18: 404 | E18: -1 | F18: 0 | G18: 1.3962e-08 | H18: 0
B19: 9 | C19: 9 | D19: 402 | E19: -1 | F19: 0 | G19: 1.434e-08 | H19: 0
B20: 10 | C20: 10 | D20: 400 | E20: -2 | F20: 0 | G20: 1.3587e-08 | H20: 0
B21: 11 | C21: 11 | D21: 398 | E21: -2 | F21: 0 | G21: 1.4273e-08 | H21: 0
B22: 12 | C22: 12 | D22: 396 | E22: -2 | F22: 0 | G22: 1.4355e-08 | H22: 0
... B97: 103 | C97: 103 | D97: 214 | E97: -1 | F97: 0 | G97: 2.476e-08 | H97: 0

Sheet Plan20 (2)
B1: STATISTICS | C1: FOR | D1: FILE: | E1: -10 | F1: mA | G1: NPLC | H1: 20 | I1: ini | J1: 2023 | K1: trecho | L1: 05.txt
B2: Frequency | C2: Data | D2: Points | E2: 1 | F2: thru | G2: 420 | H2: of | I2: 420
B3: Maximum | C3: = | D3: -0.009998447
B4: Minimum | C4: = | D4: -0.009998919
B5: Average | C5: = | D5: -0.009998645
B6: Sigma | C6: Type: | D6: Overlapping | E6: Allan
B7: Confidence | C7: Factor | D7: = | E7: 0.683
B8: Deadtime | C8: T/Tau | D8: = | E8: 1
B10: AF | C10: Tau | D10: # | E10: Alpha | F10: Min | G10: Sigma | H10: Sigma | I10: Max | J10: Sigma
B11: 1 | C11: 1 | D11: 419 | E11: 0 | F11: 0 | G11: 6.2845e-08 | H11: 0
B12: 2 | C12: 2 | D12: 417 | E12: 0 | F12: 0 | G12: 2.5024e-08 | H12: 0
B13: 3 | C13: 3 | D13: 415 | E13: 0 | F13: 0 | G13: 2.1692e-08 | H13: 0
B14: 4 | C14: 4 | D14: 413 | E14: 0 | F14: 0 | G14: 1.8051e-08 | H14: 0
B15: 5 | C15: 5 | D15: 411 | E15: 0 | F15: 0 | G15: 1.6457e-08 | H15: 0
B16: 6 | C16: 6 | D16: 409 | E16: 0 | F16: 0 | G16: 1.4996e-08 | H16: 0
B17: 7 | C17: 7 | D17: 407 | E17: -2 | F17: 0 | G17: 1.2681e-08 | H17: 0
B18: 8 | C18: 8 | D18: 405 | E18: -1 | F18: 0 | G18: 1.3219e-08 | H18: 0
B19: 9 | C19: 9 | D19: 403 | E19: -1 | F19: 0 | G19: 1.1623e-08 | H19: 0
B20: 10 | C20: 10 | D20: 401 | E20: -2 | F20: 0 | G20: 1.1746e-08 | H20: 0
B21: 11 | C21: 11 | D21: 399 | E21: -2 | F21: 0 | G21: 1.1271e-08 | H21: 0
B22: 12 | C22: 12 | D22: 397 | E22: -2 | F22: 0 | G22: 1.1463e-08 | H22: 0
... B97: 103 | C97: 103 | D97: 215 | E97: -1 | F97: 0 | G97: 2.0709e-08 | H97: 0

Sheet Plan11 (3)
B1: STATISTICS | C1: FOR | D1: FILE: | E1: 3 | F1: mA | G1: NPLC | H1: 20 | I1: ini | J1: 2023 | K1: trecho | L1: 01.txt
B2: Frequency | C2: Data | D2: Points | E2: 1 | F2: thru | G2: 419 | H2: of | I2: 419
B3: Maximum | C3: = | D3: 0.002999244
B4: Minimum | C4: = | D4: 0.002999139
B5: Average | C5: = | D5: 0.002999198
B6: Sigma | C6: Type: | D6: Overlapping | E6: Allan
B7: Confidence | C7: Factor | D7: = | E7: 0.683
B8: Deadtime | C8: T/Tau | D8: = | E8: 1
B10: AF | C10: Tau | D10: # | E10: Alpha | F10: Min | G10: Sigma | H10: Sigma | I10: Max | J10: Sigma
B11: 1 | C11: 1 | D11: 418 | E11: 1 | F11: 0 | G11: 2.3197e-08 | H11: 0
B12: 2 | C12: 2 | D12: 416 | E12: 1 | F12: 0 | G12: 1.3367e-08 | H12: 0
B13: 3 | C13: 3 | D13: 414 | E13: 0 | F13: 0 | G13: 6.6352e-09 | H13: 0
B14: 4 | C14: 4 | D14: 412 | E14: 0 | F14: 0 | G14: 6.4974e-09 | H14: 0
B15: 5 | C15: 5 | D15: 410 | E15: 1 | F15: 0 | G15: 6.5049e-09 | H15: 0
B16: 6 | C16: 6 | D16: 408 | E16: 0 | F16: 0 | G16: 4.8981e-09 | H16: 0
B17: 7 | C17: 7 | D17: 406 | E17: 0 | F17: 0 | G17: 3.5705e-09 | H17: 0
B18: 8 | C18: 8 | D18: 404 | E18: 0 | F18: 0 | G18: 4.0362e-09 | H18: 0
B19: 9 | C19: 9 | D19: 402 | E19: 0 | F19: 0 | G19: 3.6854e-09 | H19: 0
B20: 10 | C20: 10 | D20: 400 | E20: 0 | F20: 0 | G20: 2.8512e-09 | H20: 0
B21: 11 | C21: 11 | D21: 398 | E21: 0 | F21: 0 | G21: 3.1085e-09 | H21: 0
B22: 12 | C22: 12 | D22: 396 | E22: 0 | F22: 0 | G22: 3.1073e-09 | H22: 0
... B97: 103 | C97: 103 | D97: 214 | E97: -1 | F97: 0 | G97: 1.1674e-09 | H97: 0

Sheet Plan12 (3)
B1: STATISTICS | C1: FOR | D1: FILE: | E1: 3 | F1: mA | G1: NPLC | H1: 20 | I1: ini | J1: 2023 | K1: trecho | L1: 02.txt
B2: Frequency | C2: Data | D2: Points | E2: 1 | F2: thru | G2: 419 | H2: of | I2: 419
B3: Maximum | C3: = | D3: 0.002999244
B4: Minimum | C4: = | D4: 0.002999151
B5: Average | C5: = | D5: 0.002999206
B6: Sigma | C6: Type: | D6: Overlapping | E6: Allan
B7: Confidence | C7: Factor | D7: = | E7: 0.683
B8: Deadtime | C8: T/Tau | D8: = | E8: 1
B10: AF | C10: Tau | D10: # | E10: Alpha | F10: Min | G10: Sigma | H10: Sigma | I10: Max | J10: Sigma
B11: 1 | C11: 1 | D11: 418 | E11: 1 | F11: 0 | G11: 2.2162e-08 | H11: 0
B12: 2 | C12: 2 | D12: 416 | E12: 1 | F12: 0 | G12: 1.3191e-08 | H12: 0
B13: 3 | C13: 3 | D13: 414 | E13: 0 | F13: 0 | G13: 6.5991e-09 | H13: 0
B14: 4 | C14: 4 | D14: 412 | E14: 0 | F14: 0 | G14: 6.5893e-09 | H14: 0
B15: 5 | C15: 5 | D15: 410 | E15: 0 | F15: 0 | G15: 6.6104e-09 | H15: 0
B16: 6 | C16: 6 | D16: 408 | E16: 0 | F16: 0 | G16: 5.0258e-09 | H16: 0
B17: 7 | C17: 7 | D17: 406 | E17: 0 | F17: 0 | G17: 3.9846e-09 | H17: 0
B18: 8 | C18: 8 | D18: 404 | E18: 0 | F18: 0 | G18: 4.24e-09 | H18: 0
B19: 9 | C19: 9 | D19: 402 | E19: 0 | F19: 0 | G19: 3.8471e-09 | H19: 0
B20: 10 | C20: 10 | D20: 400 | E20: -1 | F20: 0 | G20: 3.1761e-09 | H20: 0
B21: 11 | C21: 11 | D21: 398 | E21: -1 | F21: 0 | G21: 3.3596e-09 | H21: 0
B22: 12 | C22: 12 | D22: 396 | E22: -1 | F22: 0 | G22: 3.2932e-09 | H22: 0
... B97: 103 | C97: 103 | D97: 214 | E97: 0 | F97: 0 | G97: 1.7233e-09 | H97: 0

Sheet Plan13 (3)
B1: STATISTICS | C1: FOR | D1: FILE: | E1: 3 | F1: mA | G1: NPLC | H1: 20 | I1: ini | J1: 2023 | K1: trecho | L1: 03.txt
B2: Frequency | C2: Data | D2: Points | E2: 1 | F2: thru | G2: 419 | H2: of | I2: 419
B3: Maximum | C3: = | D3: 0.002999252
B4: Minimum | C4: = | D4: 0.002999139
B5: Average | C5: = | D5: 0.00299921
B6: Sigma | C6: Type: | D6: Overlapping | E6: Allan
B7: Confidence | C7: Factor | D7: = | E7: 0.683
B8: Deadtime | C8: T/Tau | D8: = | E8: 1
B10: AF | C10: Tau | D10: # | E10: Alpha | F10: Min | G10: Sigma | H10: Sigma | I10: Max | J10: Sigma
B11: 1 | C11: 1 | D11: 418 | E11: 1 | F11: 0 | G11: 2.2592e-08 | H11: 0
B12: 2 | C12: 2 | D12: 416 | E12: 1 | F12: 0 | G12: 1.3239e-08 | H12: 0
B13: 3 | C13: 3 | D13: 414 | E13: 0 | F13: 0 | G13: 7.0271e-09 | H13: 0
B14: 4 | C14: 4 | D14: 412 | E14: 0 | F14: 0 | G14: 6.5659e-09 | H14: 0
B15: 5 | C15: 5 | D15: 410 | E15: 0 | F15: 0 | G15: 6.3381e-09 | H15: 0
B16: 6 | C16: 6 | D16: 408 | E16: 0 | F16: 0 | G16: 4.9193e-09 | H16: 0
B17: 7 | C17: 7 | D17: 406 | E17: 0 | F17: 0 | G17: 3.6541e-09 | H17: 0
B18: 8 | C18: 8 | D18: 404 | E18: 0 | F18: 0 | G18: 4.1944e-09 | H18: 0
B19: 9 | C19: 9 | D19: 402 | E19: 0 | F19: 0 | G19: 3.9404e-09 | H19: 0
B20: 10 | C20: 10 | D20: 400 | E20: 0 | F20: 0 | G20: 3.154e-09 | H20: 0
B21: 11 | C21: 11 | D21: 398 | E21: -1 | F21: 0 | G21: 3.3011e-09 | H21: 0
B22: 12 | C22: 12 | D22: 396 | E22: -1 | F22: 0 | G22: 3.2846e-09 | H22: 0
... B97: 103 | C97: 103 | D97: 214 | E97: -1 | F97: 0 | G97: 2.0851e-09 | H97: 0

Sheet Plan14 (3)
B1: STATISTICS | C1: FOR | D1: FILE: | E1: 3 | F1: mA | G1: NPLC | H1: 20 | I1: ini | J1: 2023 | K1: trecho | L1: 04.txt
B2: Frequency | C2: Data | D2: Points | E2: 1 | F2: thru | G2: 419 | H2: of | I2: 419
B3: Maximum | C3: = | D3: 0.002999248
B4: Minimum | C4: = | D4: 0.002999157
B5: Average | C5: = | D5: 0.002999211
B6: Sigma | C6: Type: | D6: Overlapping | E6: Allan
B7: Confidence | C7: Factor | D7: = | E7: 0.683
B8: Deadtime | C8: T/Tau | D8: = | E8: 1
B10: AF | C10: Tau | D10: # | E10: Alpha | F10: Min | G10: Sigma | H10: Sigma | I10: Max | J10: Sigma
B11: 1 | C11: 1 | D11: 418 | E11: 1 | F11: 0 | G11: 2.2303e-08 | H11: 0
B12: 2 | C12: 2 | D12: 416 | E12: 1 | F12: 0 | G12: 1.2744e-08 | H12: 0
B13: 3 | C13: 3 | D13: 414 | E13: 0 | F13: 0 | G13: 6.6048e-09 | H13: 0
B14: 4 | C14: 4 | D14: 412 | E14: 0 | F14: 0 | G14: 6.9001e-09 | H14: 0
B15: 5 | C15: 5 | D15: 410 | E15: 1 | F15: 0 | G15: 6.6572e-09 | H15: 0
B16: 6 | C16: 6 | D16: 408 | E16: 0 | F16: 0 | G16: 5.2064e-09 | H16: 0
B17: 7 | C17: 7 | D17: 406 | E17: 0 | F17: 0 | G17: 4.2929e-09 | H17: 0
B18: 8 | C18: 8 | D18: 404 | E18: 0 | F18: 0 | G18: 4.4077e-09 | H18: 0
B19: 9 | C19: 9 | D19: 402 | E19: 0 | F19: 0 | G19: 4.0734e-09 | H19: 0
B20: 10 | C20: 10 | D20: 400 | E20: 0 | F20: 0 | G20: 3.4362e-09 | H20: 0
B21: 11 | C21: 11 | D21: 398 | E21: 0 | F21: 0 | G21: 3.4977e-09 | H21: 0
B22: 12 | C22: 12 | D22: 396 | E22: 0 | F22: 0 | G22: 3.4985e-09 | H22: 0
... B97: 103 | C97: 103 | D97: 214 | E97: 0 | F97: 0 | G97: 1.8033e-09 | H97: 0

Sheet Plan15 (3)
B1: STATISTICS | C1: FOR | D1: FILE: | E1: 3 | F1: mA | G1: NPLC | H1: 20 | I1: ini | J1: 2023 | K1: trecho | L1: 05.txt
B2: Frequency | C2: Data | D2: Points | E2: 1 | F2: thru | G2: 419 | H2: of | I2: 419
B3: Maximum | C3: = | D3: 0.002999256
B4: Minimum | C4: = | D4: 0.002999154
B5: Average | C5: = | D5: 0.002999214
B6: Sigma | C6: Type: | D6: Overlapping | E6: Allan
B7: Confidence | C7: Factor | D7: = | E7: 0.683
B8: Deadtime | C8: T/Tau | D8: = | E8: 1
B10: AF | C10: Tau | D10: # | E10: Alpha | F10: Min | G10: Sigma | H10: Sigma | I10: Max | J10: Sigma
B11: 1 | C11: 1 | D11: 418 | E11: 1 | F11: 0 | G11: 2.2787e-08 | H11: 0
B12: 2 | C12: 2 | D12: 416 | E12: 1 | F12: 0 | G12: 1.2908e-08 | H12: 0
B13: 3 | C13: 3 | D13: 414 | E13: 0 | F13: 0 | G13: 6.6794e-09 | H13: 0
B14: 4 | C14: 4 | D14: 412 | E14: 0 | F14: 0 | G14: 6.8698e-09 | H14: 0
B15: 5 | C15: 5 | D15: 410 | E15: 1 | F15: 0 | G15: 6.8604e-09 | H15: 0
B16: 6 | C16: 6 | D16: 408 | E16: 0 | F16: 0 | G16: 5.1993e-09 | H16: 0
B17: 7 | C17: 7 | D17: 406 | E17: 0 | F17: 0 | G17: 3.9693e-09 | H17: 0
B18: 8 | C18: 8 | D18: 404 | E18: 0 | F18: 0 | G18: 4.3268e-09 | H18: 0
B19: 9 | C19: 9 | D19: 402 | E19: 0 | F19: 0 | G19: 3.8205e-09 | H19: 0
B20: 10 | C20: 10 | D20: 400 | E20: 0 | F20: 0 | G20: 3.0435e-09 | H20: 0
B21: 11 | C21: 11 | D21: 398 | E21: 0 | F21: 0 | G21: 3.3659e-09 | H21: 0
B22: 12 | C22: 12 | D22: 396 | E22: 0 | F22: 0 | G22: 3.3231e-09 | H22: 0
... B97: 103 | C97: 103 | D97: 214 | E97: 0 | F97: 0 | G97: 2.0798e-09 | H97: 0

Sheet Plan16 (3)
B1: STATISTICS | C1: FOR | D1: FILE: | E1: -3 | F1: mA | G1: NPLC | H1: 20 | I1: ini | J1: 2023 | K1: trecho | L1: 01.txt
B2: Frequency | C2: Data | D2: Points | E2: 1 | F2: thru | G2: 419 | H2: of | I2: 419
B3: Maximum | C3: = | D3: -0.003000586
B4: Minimum | C4: = | D4: -0.003000697
B5: Average | C5: = | D5: -0.003000631
B6: Sigma | C6: Type: | D6: Overlapping | E6: Allan
B7: Confidence | C7: Factor | D7: = | E7: 0.683
B8: Deadtime | C8: T/Tau | D8: = | E8: 1
B10: AF | C10: Tau | D10: # | E10: Alpha | F10: Min | G10: Sigma | H10: Sigma | I10: Max | J10: Sigma
B11: 1 | C11: 1 | D11: 418 | E11: 1 | F11: 0 | G11: 2.3272e-08 | H11: 0
B12: 2 | C12: 2 | D12: 416 | E12: 1 | F12: 0 | G12: 1.3516e-08 | H12: 0
B13: 3 | C13: 3 | D13: 414 | E13: 0 | F13: 0 | G13: 6.5092e-09 | H13: 0
B14: 4 | C14: 4 | D14: 412 | E14: 0 | F14: 0 | G14: 6.3863e-09 | H14: 0
B15: 5 | C15: 5 | D15: 410 | E15: 1 | F15: 0 | G15: 6.3997e-09 | H15: 0
B16: 6 | C16: 6 | D16: 408 | E16: 0 | F16: 0 | G16: 4.8292e-09 | H16: 0
B17: 7 | C17: 7 | D17: 406 | E17: 0 | F17: 0 | G17: 3.8368e-09 | H17: 0
B18: 8 | C18: 8 | D18: 404 | E18: 0 | F18: 0 | G18: 4.2001e-09 | H18: 0
B19: 9 | C19: 9 | D19: 402 | E19: 0 | F19: 0 | G19: 3.8226e-09 | H19: 0
B20: 10 | C20: 10 | D20: 400 | E20: 0 | F20: 0 | G20: 3.1542e-09 | H20: 0
B21: 11 | C21: 11 | D21: 398 | E21: 0 | F21: 0 | G21: 3.1796e-09 | H21: 0
B22: 12 | C22: 12 | D22: 396 | E22: 0 | F22: 0 | G22: 3.1787e-09 | H22: 0
... B97: 103 | C97: 103 | D97: 214 | E97: 0 | F97: 0 | G97: 1.5236e-09 | H97: 0

Sheet Plan17 (3)
B1: STATISTICS | C1: FOR | D1: FILE: | E1: -3 | F1: mA | G1: NPLC | H1: 20 | I1: ini | J1: 2023 | K1: trecho | L1: 02.txt
B2: Frequency | C2: Data | D2: Points | E2: 1 | F2: thru | G2: 419 | H2: of | I2: 419
B3: Maximum | C3: = | D3: -0.003000588
B4: Minimum | C4: = | D4: -0.003000696
B5: Average | C5: = | D5: -0.003000629
B6: Sigma | C6: Type: | D6: Overlapping | E6: Allan
B7: Confidence | C7: Factor | D7: = | E7: 0.683
B8: Deadtime | C8: T/Tau | D8: = | E8: 1
B10: AF | C10: Tau | D10: # | E10: Alpha | F10: Min | G10: Sigma | H10: Sigma | I10: Max | J10: Sigma
B11: 1 | C11: 1 | D11: 418 | E11: 1 | F11: 0 | G11: 2.304e-08 | H11: 0
B12: 2 | C12: 2 | D12: 416 | E12: 1 | F12: 0 | G12: 1.2725e-08 | H12: 0
B13: 3 | C13: 3 | D13: 414 | E13: 0 | F13: 0 | G13: 7.1085e-09 | H13: 0
B14: 4 | C14: 4 | D14: 412 | E14: 0 | F14: 0 | G14: 7.0939e-09 | H14: 0
B15: 5 | C15: 5 | D15: 410 | E15: 0 | F15: 0 | G15: 6.2786e-09 | H15: 0
B16: 6 | C16: 6 | D16: 408 | E16: 0 | F16: 0 | G16: 5.1641e-09 | H16: 0
B17: 7 | C17: 7 | D17: 406 | E17: 0 | F17: 0 | G17: 4.3601e-09 | H17: 0
B18: 8 | C18: 8 | D18: 404 | E18: 0 | F18: 0 | G18: 4.425e-09 | H18: 0
B19: 9 | C19: 9 | D19: 402 | E19: -1 | F19: 0 | G19: 4.0266e-09 | H19: 0
B20: 10 | C20: 10 | D20: 400 | E20: -1 | F20: 0 | G20: 3.5629e-09 | H20: 0
B21: 11 | C21: 11 | D21: 398 | E21: -1 | F21: 0 | G21: 3.7845e-09 | H21: 0
B22: 12 | C22: 12 | D22: 396 | E22: -1 | F22: 0 | G22: 3.5663e-09 | H22: 0
... B97: 103 | C97: 103 | D97: 214 | E97: -1 | F97: 0 | G97: 2.002e-09 | H97: 0

Sheet Plan18 (3)
B1: STATISTICS | C1: FOR | D1: FILE: | E1: -3 | F1: mA | G1: NPLC | H1: 20 | I1: ini | J1: 2023 | K1: trecho | L1: 03.txt
B2: Frequency | C2: Data | D2: Points | E2: 1 | F2: thru | G2: 419 | H2: of | I2: 419
B3: Maximum | C3: = | D3: -0.003000584
B4: Minimum | C4: = | D4: -0.003000688
B5: Average | C5: = | D5: -0.003000627
B6: Sigma | C6: Type: | D6: Overlapping | E6: Allan
B7: Confidence | C7: Factor | D7: = | E7: 0.683
B8: Deadtime | C8: T/Tau | D8: = | E8: 1
B10: AF | C10: Tau | D10: # | E10: Alpha | F10: Min | G10: Sigma | H10: Sigma | I10: Max | J10: Sigma
B11: 1 | C11: 1 | D11: 418 | E11: 1 | F11: 0 | G11: 2.3707e-08 | H11: 0
B12: 2 | C12: 2 | D12: 416 | E12: 0 | F12: 0 | G12: 1.2785e-08 | H12: 0
B13: 3 | C13: 3 | D13: 414 | E13: 0 | F13: 0 | G13: 6.6512e-09 | H13: 0
B14: 4 | C14: 4 | D14: 412 | E14: 0 | F14: 0 | G14: 6.379e-09 | H14: 0
B15: 5 | C15: 5 | D15: 410 | E15: 0 | F15: 0 | G15: 6.3176e-09 | H15: 0
B16: 6 | C16: 6 | D16: 408 | E16: 0 | F16: 0 | G16: 5.2408e-09 | H16: 0
B17: 7 | C17: 7 | D17: 406 | E17: -1 | F17: 0 | G17: 4.0779e-09 | H17: 0
B18: 8 | C18: 8 | D18: 404 | E18: 0 | F18: 0 | G18: 4.5295e-09 | H18: 0
B19: 9 | C19: 9 | D19: 402 | E19: -1 | F19: 0 | G19: 4.1773e-09 | H19: 0
B20: 10 | C20: 10 | D20: 400 | E20: -1 | F20: 0 | G20: 3.5363e-09 | H20: 0
B21: 11 | C21: 11 | D21: 398 | E21: -1 | F21: 0 | G21: 3.7362e-09 | H21: 0
B22: 12 | C22: 12 | D22: 396 | E22: -1 | F22: 0 | G22: 3.6516e-09 | H22: 0
... B97: 103 | C97: 103 | D97: 214 | E97: -1 | F97: 0 | G97: 2.4012e-09 | H97: 0

Sheet Plan19 (3)
B1: STATISTICS | C1: FOR | D1: FILE: | E1: -3 | F1: mA | G1: NPLC | H1: 20 | I1: ini | J1: 2023 | K1: trecho | L1: 04.txt
B2: Frequency | C2: Data | D2: Points | E2: 1 | F2: thru | G2: 419 | H2: of | I2: 419
B3: Maximum | C3: = | D3: -0.00300059
B4: Minimum | C4: = | D4: -0.003000691
B5: Average | C5: = | D5: -0.003000627
B6: Sigma | C6: Type: | D6: Overlapping | E6: Allan
B7: Confidence | C7: Factor | D7: = | E7: 0.683
B8: Deadtime | C8: T/Tau | D8: = | E8: 1
B10: AF | C10: Tau | D10: # | E10: Alpha | F10: Min | G10: Sigma | H10: Sigma | I10: Max | J10: Sigma
B11: 1 | C11: 1 | D11: 418 | E11: 1 | F11: 0 | G11: 2.3425e-08 | H11: 0
B12: 2 | C12: 2 | D12: 416 | E12: 1 | F12: 0 | G12: 1.3228e-08 | H12: 0
B13: 3 | C13: 3 | D13: 414 | E13: 0 | F13: 0 | G13: 7.305e-09 | H13: 0
B14: 4 | C14: 4 | D14: 412 | E14: 0 | F14: 0 | G14: 6.9711e-09 | H14: 0
B15: 5 | C15: 5 | D15: 410 | E15: 0 | F15: 0 | G15: 6.5661e-09 | H15: 0
B16: 6 | C16: 6 | D16: 408 | E16: 0 | F16: 0 | G16: 5.3166e-09 | H16: 0
B17: 7 | C17: 7 | D17: 406 | E17: 0 | F17: 0 | G17: 4.0165e-09 | H17: 0
B18: 8 | C18: 8 | D18: 404 | E18: 0 | F18: 0 | G18: 4.1618e-09 | H18: 0
B19: 9 | C19: 9 | D19: 402 | E19: 0 | F19: 0 | G19: 3.9627e-09 | H19: 0
B20: 10 | C20: 10 | D20: 400 | E20: 0 | F20: 0 | G20: 3.2672e-09 | H20: 0
B21: 11 | C21: 11 | D21: 398 | E21: 0 | F21: 0 | G21: 3.286e-09 | H21: 0
B22: 12 | C22: 12 | D22: 396 | E22: 0 | F22: 0 | G22: 3.2591e-09 | H22: 0
... B97: 103 | C97: 103 | D97: 214 | E97: -1 | F97: 0 | G97: 1.6526e-09 | H97: 0

Sheet Plan20 (3)
B1: STATISTICS | C1: FOR | D1: FILE: | E1: -3 | F1: mA | G1: NPLC | H1: 20 | I1: ini | J1: 2023 | K1: trecho | L1: 05.txt
B2: Frequency | C2: Data | D2: Points | E2: 1 | F2: thru | G2: 420 | H2: of | I2: 420
B3: Maximum | C3: = | D3: -0.003000592
